{
    "registryname": "chaosreactor",
    "localizedname": "混沌反应炉",
    "parts": [
        {
            "x": 0,
            "y": 0,
            "z": 0,
            "elements": [
                "modularmachinery:blockfactorycontroller@2"
            ]
        },
        {
            "x": -3,
            "y": -2,
            "z": 5,
            "elements": [
                "draconicevolution:draconium_block@0"
            ]
        },
        {
            "x": -6,
            "y": 8,
            "z": 5,
            "elements": [
                "draconicevolution:infused_obsidian@0"
            ]
        },
        {
            "x": 0,
            "y": -2,
            "z": 0,
            "elements": [
                "draconicevolution:draconium_block@0"
            ]
        },
        {
            "x": 3,
            "y": -2,
            "z": 14,
            "elements": [
                "draconicevolution:draconium_block@0"
            ]
        },
        {
            "x": -6,
            "y": -2,
            "z": -1,
            "elements": [
                "draconicevolution:draconium_block@0"
            ]
        },
        {
            "x": -4,
            "y": -2,
            "z": 10,
            "elements": [
                "draconicevolution:draconium_block@0"
            ]
        },
        {
            "x": 3,
            "y": -2,
            "z": 9,
            "elements": [
                "draconicevolution:draconium_block@0"
            ]
        },
        {
            "x": 5,
            "y": -2,
            "z": 1,
            "elements": [
                "draconicevolution:draconium_block@0"
            ]
        },
        {
            "x": -4,
            "y": 4,
            "z": 5,
            "elements": [
                "draconicevolution:infused_obsidian@0"
            ]
        },
        {
            "x": -7,
            "y": -2,
            "z": 11,
            "elements": [
                "draconicevolution:draconium_block@0"
            ]
        },
        {
            "x": 0,
            "y": -1,
            "z": 0,
            "elements": [
                "chisel:blockinvar@6"
            ]
        },
        {
            "x": -1,
            "y": 11,
            "z": 1,
            "elements": [
                "mekanism:basicblock@10"
            ]
        },
        {
            "x": -6,
            "y": 7,
            "z": 5,
            "elements": [
                "draconicevolution:infused_obsidian@0"
            ]
        },
        {
            "x": -5,
            "y": 1,
            "z": 6,
            "elements": [
                "chisel:blockinvar@6"
            ]
        },
        {
            "x": 5,
            "y": -1,
            "z": 1,
            "elements": [
                "modularmachinery:blockinputbus",
                "modularmachinery:blockmepatternprovider",
                "modularmachinery:blockmeiteminputbus"
            ]
        },
        {
            "x": -5,
            "y": 5,
            "z": 5,
            "elements": [
                "mekanism:basicblock@10"
            ]
        },
        {
            "x": -4,
            "y": -2,
            "z": 5,
            "elements": [
                "draconicevolution:draconium_block@0"
            ]
        },
        {
            "x": -6,
            "y": -1,
            "z": 6,
            "elements": [
                "chisel:blockinvar@6"
            ]
        },
        {
            "x": 1,
            "y": -2,
            "z": 0,
            "elements": [
                "draconicevolution:draconium_block@0"
            ]
        },
        {
            "x": -8,
            "y": -2,
            "z": 12,
            "elements": [
                "draconicevolution:draconium_block@0"
            ]
        },
        {
            "x": -7,
            "y": -2,
            "z": 4,
            "elements": [
                "draconicevolution:draconium_block@0"
            ]
        },
        {
            "x": -5,
            "y": -2,
            "z": 10,
            "elements": [
                "draconicevolution:draconium_block@0"
            ]
        },
        {
            "x": -6,
            "y": -2,
            "z": 6,
            "elements": [
                "draconicevolution:draconium_block@0"
            ]
        },
        {
            "x": 0,
            "y": 14,
            "z": 3,
            "elements": [
                "botania:quartzstairsred@2"
            ]
        },
        {
            "x": -6,
            "y": 9,
            "z": 5,
            "elements": [
                "draconicevolution:infused_obsidian@0"
            ]
        },
        {
            "x": -2,
            "y": 2,
            "z": 5,
            "elements": [
                "draconicevolution:infused_obsidian@0"
            ]
        },
        {
            "x": -3,
            "y": 12,
            "z": 4,
            "elements": [
                "draconicevolution:infused_obsidian@0"
            ]
        },
        {
            "x": 8,
            "y": -2,
            "z": 7,
            "elements": [
                "draconicevolution:draconium_block@0"
            ]
        },
        {
            "x": 0,
            "y": 14,
            "z": 4,
            "elements": [
                "draconicevolution:infused_obsidian@0"
            ]
        },
        {
            "x": -2,
            "y": 7,
            "z": 0,
            "elements": [
                "mekanism:basicblock@10"
            ]
        },
        {
            "x": 6,
            "y": -2,
            "z": 13,
            "elements": [
                "draconicevolution:draconium_block@0"
            ]
        },
        {
            "x": -2,
            "y": -2,
            "z": 0,
            "elements": [
                "draconicevolution:draconium_block@0"
            ]
        },
        {
            "x": -1,
            "y": -2,
            "z": 5,
            "elements": [
                "draconicevolution:draconium_block@0"
            ]
        },
        {
            "x": -2,
            "y": -2,
            "z": 10,
            "elements": [
                "draconicevolution:draconium_block@0"
            ]
        },
        {
            "x": 7,
            "y": -2,
            "z": 1,
            "elements": [
                "draconicevolution:draconium_block@0"
            ]
        },
        {
            "x": 8,
            "y": -2,
            "z": -1,
            "elements": [
                "draconicevolution:draconium_block@0"
            ]
        },
        {
            "x": -2,
            "y": 8,
            "z": 0,
            "elements": [
                "draconicevolution:infused_obsidian@0"
            ]
        },
        {
            "x": 7,
            "y": -2,
            "z": 8,
            "elements": [
                "draconicevolution:draconium_block@0"
            ]
        },
        {
            "x": -1,
            "y": -2,
            "z": 11,
            "elements": [
                "draconicevolution:draconium_block@0"
            ]
        },
        {
            "x": -6,
            "y": 10,
            "z": 5,
            "elements": [
                "mekanism:basicblock@10"
            ]
        },
        {
            "x": -1,
            "y": 14,
            "z": 4,
            "elements": [
                "draconicevolution:infused_obsidian@0"
            ]
        },
        {
            "x": 0,
            "y": 14,
            "z": 8,
            "elements": [
                "draconicevolution:infused_obsidian@0"
            ]
        },
        {
            "x": 3,
            "y": -2,
            "z": 0,
            "elements": [
                "draconicevolution:draconium_block@0"
            ]
        },
        {
            "x": -6,
            "y": -2,
            "z": 5,
            "elements": [
                "draconicevolution:draconium_block@0"
            ]
        },
        {
            "x": -7,
            "y": -2,
            "z": -1,
            "elements": [
                "draconicevolution:draconium_block@0"
            ]
        },
        {
            "x": -6,
            "y": 6,
            "z": 5,
            "elements": [
                "mekanism:basicblock@10"
            ]
        },
        {
            "x": -7,
            "y": -2,
            "z": 10,
            "elements": [
                "draconicevolution:draconium_block@0"
            ]
        },
        {
            "x": 8,
            "y": -2,
            "z": 1,
            "elements": [
                "draconicevolution:draconium_block@0"
            ]
        },
        {
            "x": 0,
            "y": 2,
            "z": 5,
            "elements": [
                "draconicevolution:infused_obsidian@0"
            ]
        },
        {
            "x": -3,
            "y": 11,
            "z": 3,
            "elements": [
                "mekanism:basicblock@10"
            ]
        },
        {
            "x": 0,
            "y": -2,
            "z": 6,
            "elements": [
                "draconicevolution:draconium_block@0"
            ]
        },
        {
            "x": 0,
            "y": -2,
            "z": 11,
            "elements": [
                "draconicevolution:draconium_block@0"
            ]
        },
        {
            "x": -7,
            "y": -2,
            "z": 1,
            "elements": [
                "draconicevolution:draconium_block@0"
            ]
        },
        {
            "x": -3,
            "y": 3,
            "z": 5,
            "elements": [
                "draconicevolution:infused_obsidian@0"
            ]
        },
        {
            "x": 0,
            "y": 3,
            "z": 3,
            "elements": [
                "draconicevolution:infused_obsidian@0"
            ]
        },
        {
            "x": 4,
            "y": -2,
            "z": 0,
            "elements": [
                "draconicevolution:draconium_block@0"
            ]
        },
        {
            "x": -6,
            "y": -2,
            "z": 3,
            "elements": [
                "draconicevolution:draconium_block@0"
            ]
        },
        {
            "x": 1,
            "y": -2,
            "z": 5,
            "elements": [
                "draconicevolution:draconium_block@0"
            ]
        },
        {
            "x": 2,
            "y": -2,
            "z": 4,
            "elements": [
                "draconicevolution:draconium_block@0"
            ]
        },
        {
            "x": 6,
            "y": 2,
            "z": 6,
            "elements": [
                "chisel:blockinvar@6"
            ]
        },
        {
            "x": 3,
            "y": -2,
            "z": 6,
            "elements": [
                "draconicevolution:draconium_block@0"
            ]
        },
        {
            "x": -1,
            "y": 9,
            "z": 0,
            "elements": [
                "draconicevolution:infused_obsidian@0"
            ]
        },
        {
            "x": -8,
            "y": -2,
            "z": 10,
            "elements": [
                "draconicevolution:draconium_block@0"
            ]
        },
        {
            "x": -3,
            "y": 4,
            "z": 4,
            "elements": [
                "draconicevolution:infused_obsidian@0"
            ]
        },
        {
            "x": 5,
            "y": -2,
            "z": 7,
            "elements": [
                "draconicevolution:draconium_block@0"
            ]
        },
        {
            "x": -3,
            "y": -2,
            "z": 11,
            "elements": [
                "draconicevolution:draconium_block@0"
            ]
        },
        {
            "x": 3,
            "y": -1,
            "z": 6,
            "elements": [
                "chisel:blockinvar@6"
            ]
        },
        {
            "x": -1,
            "y": 10,
            "z": 0,
            "elements": [
                "mekanism:basicblock@10"
            ]
        },
        {
            "x": 4,
            "y": 4,
            "z": 6,
            "elements": [
                "draconicevolution:infused_obsidian@0"
            ]
        },
        {
            "x": 0,
            "y": -2,
            "z": 13,
            "elements": [
                "draconicevolution:draconium_block@0"
            ]
        },
        {
            "x": 5,
            "y": -2,
            "z": 4,
            "elements": [
                "draconicevolution:draconium_block@0"
            ]
        },
        {
            "x": 0,
            "y": 2,
            "z": 4,
            "elements": [
                "draconicevolution:infused_obsidian@0"
            ]
        },
        {
            "x": 0,
            "y": -1,
            "z": 9,
            "elements": [
                "chisel:blockinvar@6"
            ]
        },
        {
            "x": 1,
            "y": 2,
            "z": 6,
            "elements": [
                "draconicevolution:infused_obsidian@0"
            ]
        },
        {
            "x": -3,
            "y": -2,
            "z": 0,
            "elements": [
                "draconicevolution:draconium_block@0"
            ]
        },
        {
            "x": 6,
            "y": -2,
            "z": 14,
            "elements": [
                "draconicevolution:draconium_block@0"
            ]
        },
        {
            "x": -1,
            "y": -2,
            "z": 10,
            "elements": [
                "draconicevolution:draconium_block@0"
            ]
        },
        {
            "x": 6,
            "y": -2,
            "z": 6,
            "elements": [
                "draconicevolution:draconium_block@0"
            ]
        },
        {
            "x": 4,
            "y": 0,
            "z": 6,
            "elements": [
                "chisel:blockinvar@6"
            ]
        },
        {
            "x": 0,
            "y": -2,
            "z": 9,
            "elements": [
                "draconicevolution:draconium_block@0"
            ]
        },
        {
            "x": 2,
            "y": 2,
            "z": 5,
            "elements": [
                "draconicevolution:infused_obsidian@0"
            ]
        },
        {
            "x": -6,
            "y": -2,
            "z": 11,
            "elements": [
                "draconicevolution:draconium_block@0"
            ]
        },
        {
            "x": 5,
            "y": -2,
            "z": 3,
            "elements": [
                "draconicevolution:draconium_block@0"
            ]
        },
        {
            "x": 3,
            "y": -2,
            "z": 12,
            "elements": [
                "draconicevolution:draconium_block@0"
            ]
        },
        {
            "x": -3,
            "y": 13,
            "z": 6,
            "elements": [
                "draconicevolution:infused_obsidian@0"
            ]
        },
        {
            "x": 8,
            "y": -2,
            "z": 4,
            "elements": [
                "draconicevolution:draconium_block@0"
            ]
        },
        {
            "x": 6,
            "y": -1,
            "z": 6,
            "elements": [
                "chisel:blockinvar@6"
            ]
        },
        {
            "x": -4,
            "y": -2,
            "z": 4,
            "elements": [
                "draconicevolution:draconium_block@0"
            ]
        },
        {
            "x": -5,
            "y": -2,
            "z": 5,
            "elements": [
                "draconicevolution:draconium_block@0"
            ]
        },
        {
            "x": -6,
            "y": -2,
            "z": 0,
            "elements": [
                "draconicevolution:draconium_block@0"
            ]
        },
        {
            "x": -3,
            "y": 14,
            "z": 6,
            "elements": [
                "botania:quartzstairsred@0"
            ]
        },
        {
            "x": 5,
            "y": -2,
            "z": 6,
            "elements": [
                "draconicevolution:draconium_block@0"
            ]
        },
        {
            "x": 0,
            "y": 8,
            "z": 6,
            "elements": [
                "draconicevolution:reactor_core@0"
            ]
        },
        {
            "x": -1,
            "y": 6,
            "z": 0,
            "elements": [
                "mekanism:basicblock@10"
            ]
        },
        {
            "x": 0,
            "y": 0,
            "z": 10,
            "elements": [
                "chisel:blockinvar@6"
            ]
        },
        {
            "x": -1,
            "y": 2,
            "z": 5,
            "elements": [
                "draconicevolution:infused_obsidian@0"
            ]
        },
        {
            "x": 4,
            "y": -2,
            "z": 12,
            "elements": [
                "draconicevolution:draconium_block@0"
            ]
        },
        {
            "x": -5,
            "y": -2,
            "z": 11,
            "elements": [
                "draconicevolution:draconium_block@0"
            ]
        },
        {
            "x": 2,
            "y": -2,
            "z": 10,
            "elements": [
                "draconicevolution:draconium_block@0"
            ]
        },
        {
            "x": 8,
            "y": -2,
            "z": 3,
            "elements": [
                "draconicevolution:draconium_block@0"
            ]
        },
        {
            "x": -4,
            "y": -2,
            "z": 1,
            "elements": [
                "draconicevolution:draconium_block@0"
            ]
        },
        {
            "x": 0,
            "y": 4,
            "z": 10,
            "elements": [
                "draconicevolution:infused_obsidian@0"
            ]
        },
        {
            "x": -3,
            "y": -2,
            "z": 14,
            "elements": [
                "draconicevolution:draconium_block@0"
            ]
        },
        {
            "x": -8,
            "y": -2,
            "z": 5,
            "elements": [
                "draconicevolution:draconium_block@0"
            ]
        },
        {
            "x": -2,
            "y": -2,
            "z": 5,
            "elements": [
                "draconicevolution:draconium_block@0"
            ]
        },
        {
            "x": 6,
            "y": 0,
            "z": 6,
            "elements": [
                "chisel:blockinvar@6"
            ]
        },
        {
            "x": -1,
            "y": 7,
            "z": 0,
            "elements": [
                "draconicevolution:infused_obsidian@0"
            ]
        },
        {
            "x": -3,
            "y": 13,
            "z": 5,
            "elements": [
                "draconicevolution:infused_obsidian@0"
            ]
        },
        {
            "x": 0,
            "y": -2,
            "z": 14,
            "elements": [
                "draconicevolution:draconium_block@0"
            ]
        },
        {
            "x": 0,
            "y": 2,
            "z": 7,
            "elements": [
                "draconicevolution:infused_obsidian@0"
            ]
        },
        {
            "x": 6,
            "y": -2,
            "z": 9,
            "elements": [
                "draconicevolution:draconium_block@0"
            ]
        },
        {
            "x": 6,
            "y": 1,
            "z": 6,
            "elements": [
                "chisel:blockinvar@6"
            ]
        },
        {
            "x": 5,
            "y": -2,
            "z": -1,
            "elements": [
                "draconicevolution:draconium_block@0"
            ]
        },
        {
            "x": 1,
            "y": -2,
            "z": 12,
            "elements": [
                "draconicevolution:draconium_block@0"
            ]
        },
        {
            "x": 2,
            "y": -2,
            "z": 7,
            "elements": [
                "draconicevolution:draconium_block@0"
            ]
        },
        {
            "x": 3,
            "y": 3,
            "z": 6,
            "elements": [
                "draconicevolution:infused_obsidian@0"
            ]
        },
        {
            "x": -4,
            "y": -2,
            "z": 11,
            "elements": [
                "draconicevolution:draconium_block@0"
            ]
        },
        {
            "x": -1,
            "y": 8,
            "z": 0,
            "elements": [
                "draconicevolution:infused_obsidian@0"
            ]
        },
        {
            "x": 0,
            "y": 13,
            "z": 3,
            "elements": [
                "draconicevolution:infused_obsidian@0"
            ]
        },
        {
            "x": 3,
            "y": -2,
            "z": 13,
            "elements": [
                "draconicevolution:draconium_block@0"
            ]
        },
        {
            "x": -5,
            "y": -2,
            "z": 9,
            "elements": [
                "draconicevolution:draconium_block@0"
            ]
        },
        {
            "x": -2,
            "y": -2,
            "z": 4,
            "elements": [
                "draconicevolution:draconium_block@0"
            ]
        },
        {
            "x": -5,
            "y": 8,
            "z": 3,
            "elements": [
                "draconicevolution:infused_obsidian@0"
            ]
        },
        {
            "x": 5,
            "y": -2,
            "z": 5,
            "elements": [
                "draconicevolution:draconium_block@0"
            ]
        },
        {
            "x": -3,
            "y": -2,
            "z": -2,
            "elements": [
                "draconicevolution:draconium_block@0"
            ]
        },
        {
            "x": -8,
            "y": -2,
            "z": 0,
            "elements": [
                "draconicevolution:draconium_block@0"
            ]
        },
        {
            "x": 6,
            "y": -2,
            "z": 3,
            "elements": [
                "draconicevolution:draconium_block@0"
            ]
        },
        {
            "x": 5,
            "y": -2,
            "z": 8,
            "elements": [
                "draconicevolution:draconium_block@0"
            ]
        },
        {
            "x": -5,
            "y": 7,
            "z": 3,
            "elements": [
                "mekanism:basicblock@10"
            ]
        },
        {
            "x": 6,
            "y": -2,
            "z": 12,
            "elements": [
                "draconicevolution:draconium_block@0"
            ]
        },
        {
            "x": 4,
            "y": -2,
            "z": 13,
            "elements": [
                "draconicevolution:draconium_block@0"
            ]
        },
        {
            "x": 0,
            "y": 8,
            "z": 11,
            "elements": [
                "draconicevolution:reactor_component@0"
            ]
        },
        {
            "x": 4,
            "y": -2,
            "z": 2,
            "elements": [
                "draconicevolution:draconium_block@0"
            ]
        },
        {
            "x": 7,
            "y": -2,
            "z": 0,
            "elements": [
                "draconicevolution:draconium_block@0"
            ]
        },
        {
            "x": 0,
            "y": 2,
            "z": 8,
            "elements": [
                "draconicevolution:infused_obsidian@0"
            ]
        },
        {
            "x": -4,
            "y": -2,
            "z": 9,
            "elements": [
                "draconicevolution:draconium_block@0"
            ]
        },
        {
            "x": -7,
            "y": -2,
            "z": 3,
            "elements": [
                "draconicevolution:draconium_block@0"
            ]
        },
        {
            "x": -2,
            "y": 3,
            "z": 4,
            "elements": [
                "draconicevolution:infused_obsidian@0"
            ]
        },
        {
            "x": 0,
            "y": 11,
            "z": 11,
            "elements": [
                "draconicevolution:infused_obsidian@0"
            ]
        },
        {
            "x": -2,
            "y": 14,
            "z": 6,
            "elements": [
                "draconicevolution:infused_obsidian@0"
            ]
        },
        {
            "x": 1,
            "y": -2,
            "z": 4,
            "elements": [
                "draconicevolution:draconium_block@0"
            ]
        },
        {
            "x": -1,
            "y": 14,
            "z": 5,
            "elements": [
                "draconicevolution:infused_obsidian@0"
            ]
        },
        {
            "x": 4,
            "y": -2,
            "z": 5,
            "elements": [
                "draconicevolution:draconium_block@0"
            ]
        },
        {
            "x": 0,
            "y": -1,
            "z": 3,
            "elements": [
                "chisel:blockinvar@6"
            ]
        },
        {
            "x": -5,
            "y": 10,
            "z": 4,
            "elements": [
                "mekanism:basicblock@10"
            ]
        },
        {
            "x": -1,
            "y": -2,
            "z": 8,
            "elements": [
                "draconicevolution:draconium_block@0"
            ]
        },
        {
            "x": -2,
            "y": 4,
            "z": 3,
            "elements": [
                "draconicevolution:infused_obsidian@0"
            ]
        },
        {
            "x": 2,
            "y": -2,
            "z": 8,
            "elements": [
                "draconicevolution:draconium_block@0"
            ]
        },
        {
            "x": -5,
            "y": 9,
            "z": 3,
            "elements": [
                "mekanism:basicblock@10"
            ]
        },
        {
            "x": 3,
            "y": -2,
            "z": 10,
            "elements": [
                "draconicevolution:draconium_block@0"
            ]
        },
        {
            "x": 7,
            "y": -2,
            "z": 12,
            "elements": [
                "draconicevolution:draconium_block@0"
            ]
        },
        {
            "x": -1,
            "y": 2,
            "z": 4,
            "elements": [
                "draconicevolution:infused_obsidian@0"
            ]
        },
        {
            "x": -3,
            "y": -2,
            "z": 9,
            "elements": [
                "draconicevolution:draconium_block@0"
            ]
        },
        {
            "x": 0,
            "y": -2,
            "z": 4,
            "elements": [
                "draconicevolution:draconium_block@0"
            ]
        },
        {
            "x": -4,
            "y": 5,
            "z": 4,
            "elements": [
                "mekanism:basicblock@10"
            ]
        },
        {
            "x": 6,
            "y": 5,
            "z": 6,
            "elements": [
                "chisel:blockinvar@6"
            ]
        },
        {
            "x": 0,
            "y": 12,
            "z": 10,
            "elements": [
                "draconicevolution:infused_obsidian@0"
            ]
        },
        {
            "x": 7,
            "y": -2,
            "z": 5,
            "elements": [
                "draconicevolution:draconium_block@0"
            ]
        },
        {
            "x": -6,
            "y": 9,
            "z": 4,
            "elements": [
                "mekanism:basicblock@10"
            ]
        },
        {
            "x": 6,
            "y": -2,
            "z": 10,
            "elements": [
                "draconicevolution:draconium_block@0"
            ]
        },
        {
            "x": 0,
            "y": 12,
            "z": 11,
            "elements": [
                "botania:quartzstairsred@3"
            ]
        },
        {
            "x": -4,
            "y": -2,
            "z": 3,
            "elements": [
                "draconicevolution:draconium_block@0"
            ]
        },
        {
            "x": 6,
            "y": 4,
            "z": 6,
            "elements": [
                "chisel:blockinvar@6"
            ]
        },
        {
            "x": -1,
            "y": -2,
            "z": 4,
            "elements": [
                "draconicevolution:draconium_block@0"
            ]
        },
        {
            "x": -6,
            "y": -2,
            "z": -2,
            "elements": [
                "draconicevolution:draconium_block@0"
            ]
        },
        {
            "x": -7,
            "y": -2,
            "z": 8,
            "elements": [
                "draconicevolution:draconium_block@0"
            ]
        },
        {
            "x": 7,
            "y": -2,
            "z": 13,
            "elements": [
                "draconicevolution:draconium_block@0"
            ]
        },
        {
            "x": 2,
            "y": -2,
            "z": 5,
            "elements": [
                "draconicevolution:draconium_block@0"
            ]
        },
        {
            "x": -6,
            "y": -2,
            "z": 9,
            "elements": [
                "draconicevolution:draconium_block@0"
            ]
        },
        {
            "x": -6,
            "y": 8,
            "z": 4,
            "elements": [
                "draconicevolution:infused_obsidian@0"
            ]
        },
        {
            "x": -4,
            "y": 8,
            "z": 2,
            "elements": [
                "draconicevolution:infused_obsidian@0"
            ]
        },
        {
            "x": 6,
            "y": 3,
            "z": 6,
            "elements": [
                "chisel:blockinvar@6"
            ]
        },
        {
            "x": -5,
            "y": -2,
            "z": 0,
            "elements": [
                "draconicevolution:draconium_block@0"
            ]
        },
        {
            "x": 8,
            "y": -2,
            "z": 6,
            "elements": [
                "draconicevolution:draconium_block@0"
            ]
        },
        {
            "x": -1,
            "y": 4,
            "z": 2,
            "elements": [
                "draconicevolution:infused_obsidian@0"
            ]
        },
        {
            "x": 8,
            "y": -2,
            "z": 8,
            "elements": [
                "draconicevolution:draconium_block@0"
            ]
        },
        {
            "x": -5,
            "y": 6,
            "z": 4,
            "elements": [
                "mekanism:basicblock@10"
            ]
        },
        {
            "x": -6,
            "y": 7,
            "z": 4,
            "elements": [
                "mekanism:basicblock@10"
            ]
        },
        {
            "x": -4,
            "y": 12,
            "z": 5,
            "elements": [
                "draconicevolution:infused_obsidian@0"
            ]
        },
        {
            "x": 6,
            "y": -2,
            "z": 7,
            "elements": [
                "draconicevolution:draconium_block@0"
            ]
        },
        {
            "x": 3,
            "y": -2,
            "z": 3,
            "elements": [
                "draconicevolution:draconium_block@0"
            ]
        },
        {
            "x": -4,
            "y": 9,
            "z": 2,
            "elements": [
                "mekanism:basicblock@10"
            ]
        },
        {
            "x": 6,
            "y": -2,
            "z": 0,
            "elements": [
                "draconicevolution:draconium_block@0"
            ]
        },
        {
            "x": 8,
            "y": -2,
            "z": 13,
            "elements": [
                "draconicevolution:draconium_block@0"
            ]
        },
        {
            "x": -8,
            "y": -2,
            "z": 2,
            "elements": [
                "draconicevolution:draconium_block@0"
            ]
        },
        {
            "x": -6,
            "y": -2,
            "z": 4,
            "elements": [
                "draconicevolution:draconium_block@0"
            ]
        },
        {
            "x": 6,
            "y": 8,
            "z": 6,
            "elements": [
                "fluxnetworks:fluxblock@0"
            ]
        },
        {
            "x": 0,
            "y": -2,
            "z": 10,
            "elements": [
                "draconicevolution:draconium_block@0"
            ]
        },
        {
            "x": -1,
            "y": 12,
            "z": 2,
            "elements": [
                "draconicevolution:infused_obsidian@0"
            ]
        },
        {
            "x": -4,
            "y": 10,
            "z": 3,
            "elements": [
                "mekanism:basicblock@10"
            ]
        },
        {
            "x": 0,
            "y": 1,
            "z": 11,
            "elements": [
                "chisel:blockinvar@6"
            ]
        },
        {
            "x": 2,
            "y": -2,
            "z": 3,
            "elements": [
                "draconicevolution:draconium_block@0"
            ]
        },
        {
            "x": 5,
            "y": -2,
            "z": 11,
            "elements": [
                "draconicevolution:draconium_block@0"
            ]
        },
        {
            "x": -3,
            "y": -2,
            "z": 4,
            "elements": [
                "draconicevolution:draconium_block@0"
            ]
        },
        {
            "x": -2,
            "y": 9,
            "z": 0,
            "elements": [
                "mekanism:basicblock@10"
            ]
        },
        {
            "x": -8,
            "y": -2,
            "z": 9,
            "elements": [
                "draconicevolution:draconium_block@0"
            ]
        },
        {
            "x": 6,
            "y": 7,
            "z": 6,
            "elements": [
                "draconicevolution:infused_obsidian@0"
            ]
        },
        {
            "x": 6,
            "y": 6,
            "z": 6,
            "elements": [
                "draconicevolution:infused_obsidian@0"
            ]
        },
        {
            "x": 0,
            "y": 13,
            "z": 10,
            "elements": [
                "botania:quartzstairsred@3"
            ]
        },
        {
            "x": 8,
            "y": -2,
            "z": -2,
            "elements": [
                "draconicevolution:draconium_block@0"
            ]
        },
        {
            "x": 2,
            "y": -2,
            "z": 11,
            "elements": [
                "draconicevolution:draconium_block@0"
            ]
        },
        {
            "x": -3,
            "y": 5,
            "z": 3,
            "elements": [
                "mekanism:basicblock@10"
            ]
        },
        {
            "x": -3,
            "y": -2,
            "z": 3,
            "elements": [
                "draconicevolution:draconium_block@0"
            ]
        },
        {
            "x": -7,
            "y": -2,
            "z": 5,
            "elements": [
                "draconicevolution:draconium_block@0"
            ]
        },
        {
            "x": 7,
            "y": -2,
            "z": 2,
            "elements": [
                "draconicevolution:draconium_block@0"
            ]
        },
        {
            "x": 5,
            "y": -2,
            "z": 14,
            "elements": [
                "draconicevolution:draconium_block@0"
            ]
        },
        {
            "x": -4,
            "y": 6,
            "z": 3,
            "elements": [
                "mekanism:basicblock@10"
            ]
        },
        {
            "x": -6,
            "y": -2,
            "z": 10,
            "elements": [
                "draconicevolution:draconium_block@0"
            ]
        },
        {
            "x": 1,
            "y": -2,
            "z": 9,
            "elements": [
                "draconicevolution:draconium_block@0"
            ]
        },
        {
            "x": 0,
            "y": 5,
            "z": 11,
            "elements": [
                "draconicevolution:infused_obsidian@0"
            ]
        },
        {
            "x": 3,
            "y": -2,
            "z": 4,
            "elements": [
                "draconicevolution:draconium_block@0"
            ]
        },
        {
            "x": 0,
            "y": -2,
            "z": 3,
            "elements": [
                "draconicevolution:draconium_block@0"
            ]
        },
        {
            "x": 3,
            "y": -2,
            "z": 11,
            "elements": [
                "draconicevolution:draconium_block@0"
            ]
        },
        {
            "x": -2,
            "y": -2,
            "z": 9,
            "elements": [
                "draconicevolution:draconium_block@0"
            ]
        },
        {
            "x": -3,
            "y": -2,
            "z": 10,
            "elements": [
                "draconicevolution:draconium_block@0"
            ]
        },
        {
            "x": -7,
            "y": -2,
            "z": 2,
            "elements": [
                "draconicevolution:draconium_block@0"
            ]
        },
        {
            "x": 8,
            "y": -2,
            "z": 14,
            "elements": [
                "draconicevolution:draconium_block@0"
            ]
        },
        {
            "x": 1,
            "y": 2,
            "z": 4,
            "elements": [
                "draconicevolution:infused_obsidian@0"
            ]
        },
        {
            "x": 6,
            "y": -2,
            "z": -2,
            "elements": [
                "draconicevolution:draconium_block@0"
            ]
        },
        {
            "x": -1,
            "y": -2,
            "z": 3,
            "elements": [
                "draconicevolution:draconium_block@0"
            ]
        },
        {
            "x": -4,
            "y": 11,
            "z": 4,
            "elements": [
                "mekanism:basicblock@10"
            ]
        },
        {
            "x": 0,
            "y": 11,
            "z": 12,
            "elements": [
                "botania:quartzstairsred@3"
            ]
        },
        {
            "x": 2,
            "y": 2,
            "z": 6,
            "elements": [
                "draconicevolution:infused_obsidian@0"
            ]
        },
        {
            "x": -4,
            "y": -2,
            "z": 2,
            "elements": [
                "draconicevolution:draconium_block@0"
            ]
        },
        {
            "x": -6,
            "y": -2,
            "z": 8,
            "elements": [
                "draconicevolution:draconium_block@0"
            ]
        },
        {
            "x": -1,
            "y": 2,
            "z": 7,
            "elements": [
                "draconicevolution:infused_obsidian@0"
            ]
        },
        {
            "x": 7,
            "y": -2,
            "z": 6,
            "elements": [
                "draconicevolution:draconium_block@0"
            ]
        },
        {
            "x": -4,
            "y": 12,
            "z": 6,
            "elements": [
                "draconicevolution:infused_obsidian@0"
            ]
        },
        {
            "x": 5,
            "y": -2,
            "z": -2,
            "elements": [
                "draconicevolution:draconium_block@0"
            ]
        },
        {
            "x": 0,
            "y": 10,
            "z": 12,
            "elements": [
                "draconicevolution:infused_obsidian@0"
            ]
        },
        {
            "x": 0,
            "y": 4,
            "z": 2,
            "elements": [
                "draconicevolution:infused_obsidian@0"
            ]
        },
        {
            "x": -4,
            "y": -2,
            "z": 13,
            "elements": [
                "draconicevolution:draconium_block@0"
            ]
        },
        {
            "x": -2,
            "y": 11,
            "z": 2,
            "elements": [
                "mekanism:basicblock@10"
            ]
        },
        {
            "x": -4,
            "y": 13,
            "z": 6,
            "elements": [
                "botania:quartzstairsred@0"
            ]
        },
        {
            "x": -2,
            "y": -2,
            "z": 3,
            "elements": [
                "draconicevolution:draconium_block@0"
            ]
        },
        {
            "x": -6,
            "y": -2,
            "z": 1,
            "elements": [
                "draconicevolution:draconium_block@0"
            ]
        },
        {
            "x": 1,
            "y": -2,
            "z": 7,
            "elements": [
                "draconicevolution:draconium_block@0"
            ]
        },
        {
            "x": -3,
            "y": 10,
            "z": 2,
            "elements": [
                "mekanism:basicblock@10"
            ]
        },
        {
            "x": -8,
            "y": -2,
            "z": 7,
            "elements": [
                "draconicevolution:draconium_block@0"
            ]
        },
        {
            "x": 2,
            "y": -2,
            "z": 14,
            "elements": [
                "draconicevolution:draconium_block@0"
            ]
        },
        {
            "x": -4,
            "y": -2,
            "z": -2,
            "elements": [
                "draconicevolution:draconium_block@0"
            ]
        },
        {
            "x": -5,
            "y": -2,
            "z": 2,
            "elements": [
                "draconicevolution:draconium_block@0"
            ]
        },
        {
            "x": 4,
            "y": -2,
            "z": 9,
            "elements": [
                "draconicevolution:draconium_block@0"
            ]
        },
        {
            "x": 5,
            "y": 5,
            "z": 6,
            "elements": [
                "draconicevolution:infused_obsidian@0"
            ]
        },
        {
            "x": -7,
            "y": -2,
            "z": 13,
            "elements": [
                "draconicevolution:draconium_block@0"
            ]
        },
        {
            "x": -1,
            "y": -2,
            "z": 12,
            "elements": [
                "draconicevolution:draconium_block@0"
            ]
        },
        {
            "x": 7,
            "y": -2,
            "z": -1,
            "elements": [
                "draconicevolution:draconium_block@0"
            ]
        },
        {
            "x": 4,
            "y": -2,
            "z": 4,
            "elements": [
                "draconicevolution:draconium_block@0"
            ]
        },
        {
            "x": 6,
            "y": -2,
            "z": 11,
            "elements": [
                "draconicevolution:draconium_block@0"
            ]
        },
        {
            "x": 1,
            "y": -2,
            "z": 3,
            "elements": [
                "draconicevolution:draconium_block@0"
            ]
        },
        {
            "x": 2,
            "y": -2,
            "z": 2,
            "elements": [
                "draconicevolution:draconium_block@0"
            ]
        },
        {
            "x": 1,
            "y": -2,
            "z": 14,
            "elements": [
                "draconicevolution:draconium_block@0"
            ]
        },
        {
            "x": -8,
            "y": -2,
            "z": -1,
            "elements": [
                "draconicevolution:draconium_block@0"
            ]
        },
        {
            "x": 0,
            "y": 12,
            "z": 1,
            "elements": [
                "botania:quartzstairsred@2"
            ]
        },
        {
            "x": 0,
            "y": 1,
            "z": 12,
            "elements": [
                "chisel:blockinvar@6"
            ]
        },
        {
            "x": 5,
            "y": -2,
            "z": 9,
            "elements": [
                "draconicevolution:draconium_block@0"
            ]
        },
        {
            "x": -8,
            "y": -2,
            "z": 4,
            "elements": [
                "draconicevolution:draconium_block@0"
            ]
        },
        {
            "x": -1,
            "y": -2,
            "z": -2,
            "elements": [
                "draconicevolution:draconium_block@0"
            ]
        },
        {
            "x": 0,
            "y": -2,
            "z": 8,
            "elements": [
                "draconicevolution:draconium_block@0"
            ]
        },
        {
            "x": 4,
            "y": -2,
            "z": 3,
            "elements": [
                "draconicevolution:draconium_block@0"
            ]
        },
        {
            "x": 0,
            "y": 0,
            "z": 12,
            "elements": [
                "modularmachinery:blockenergyoutputhatch"
            ]
        },
        {
            "x": 1,
            "y": -2,
            "z": 6,
            "elements": [
                "draconicevolution:draconium_block@0"
            ]
        },
        {
            "x": -5,
            "y": -2,
            "z": 7,
            "elements": [
                "draconicevolution:draconium_block@0"
            ]
        },
        {
            "x": 8,
            "y": -2,
            "z": 12,
            "elements": [
                "draconicevolution:draconium_block@0"
            ]
        },
        {
            "x": 7,
            "y": -2,
            "z": 4,
            "elements": [
                "draconicevolution:draconium_block@0"
            ]
        },
        {
            "x": -8,
            "y": -2,
            "z": 1,
            "elements": [
                "draconicevolution:draconium_block@0"
            ]
        },
        {
            "x": -1,
            "y": 3,
            "z": 3,
            "elements": [
                "draconicevolution:infused_obsidian@0"
            ]
        },
        {
            "x": 0,
            "y": 0,
            "z": 2,
            "elements": [
                "chisel:blockinvar@6"
            ]
        },
        {
            "x": 0,
            "y": 3,
            "z": 9,
            "elements": [
                "draconicevolution:infused_obsidian@0"
            ]
        },
        {
            "x": -2,
            "y": 13,
            "z": 4,
            "elements": [
                "draconicevolution:infused_obsidian@0"
            ]
        },
        {
            "x": -5,
            "y": -2,
            "z": 3,
            "elements": [
                "draconicevolution:draconium_block@0"
            ]
        },
        {
            "x": 4,
            "y": -2,
            "z": 14,
            "elements": [
                "draconicevolution:draconium_block@0"
            ]
        },
        {
            "x": 2,
            "y": -2,
            "z": 9,
            "elements": [
                "draconicevolution:draconium_block@0"
            ]
        },
        {
            "x": 0,
            "y": 3,
            "z": 12,
            "elements": [
                "chisel:blockinvar@6"
            ]
        },
        {
            "x": -1,
            "y": 2,
            "z": 6,
            "elements": [
                "draconicevolution:infused_obsidian@0"
            ]
        },
        {
            "x": 2,
            "y": -2,
            "z": -2,
            "elements": [
                "draconicevolution:draconium_block@0"
            ]
        },
        {
            "x": 5,
            "y": 8,
            "z": 6,
            "elements": [
                "draconicevolution:reactor_component@0"
            ]
        },
        {
            "x": 5,
            "y": -2,
            "z": 12,
            "elements": [
                "draconicevolution:draconium_block@0"
            ]
        },
        {
            "x": 0,
            "y": 2,
            "z": 12,
            "elements": [
                "chisel:blockinvar@6"
            ]
        },
        {
            "x": -1,
            "y": -2,
            "z": 13,
            "elements": [
                "draconicevolution:draconium_block@0"
            ]
        },
        {
            "x": 6,
            "y": -2,
            "z": 4,
            "elements": [
                "draconicevolution:draconium_block@0"
            ]
        },
        {
            "x": -2,
            "y": -2,
            "z": 7,
            "elements": [
                "draconicevolution:draconium_block@0"
            ]
        },
        {
            "x": 5,
            "y": -2,
            "z": 2,
            "elements": [
                "draconicevolution:draconium_block@0"
            ]
        },
        {
            "x": 0,
            "y": -2,
            "z": 2,
            "elements": [
                "draconicevolution:draconium_block@0"
            ]
        },
        {
            "x": -1,
            "y": 2,
            "z": 8,
            "elements": [
                "draconicevolution:infused_obsidian@0"
            ]
        },
        {
            "x": -1,
            "y": -2,
            "z": 9,
            "elements": [
                "draconicevolution:draconium_block@0"
            ]
        },
        {
            "x": 8,
            "y": -2,
            "z": 11,
            "elements": [
                "draconicevolution:draconium_block@0"
            ]
        },
        {
            "x": 0,
            "y": 4,
            "z": 12,
            "elements": [
                "chisel:blockinvar@6"
            ]
        },
        {
            "x": 7,
            "y": -2,
            "z": 14,
            "elements": [
                "draconicevolution:draconium_block@0"
            ]
        },
        {
            "x": -2,
            "y": -2,
            "z": 8,
            "elements": [
                "draconicevolution:draconium_block@0"
            ]
        },
        {
            "x": 1,
            "y": -2,
            "z": -2,
            "elements": [
                "draconicevolution:draconium_block@0"
            ]
        },
        {
            "x": 2,
            "y": -2,
            "z": 12,
            "elements": [
                "draconicevolution:draconium_block@0"
            ]
        },
        {
            "x": -2,
            "y": 6,
            "z": 1,
            "elements": [
                "mekanism:basicblock@10"
            ]
        },
        {
            "x": -3,
            "y": 6,
            "z": 2,
            "elements": [
                "mekanism:basicblock@10"
            ]
        },
        {
            "x": 0,
            "y": 5,
            "z": 12,
            "elements": [
                "chisel:blockinvar@6"
            ]
        },
        {
            "x": -4,
            "y": 7,
            "z": 2,
            "elements": [
                "mekanism:basicblock@10"
            ]
        },
        {
            "x": -2,
            "y": -2,
            "z": -1,
            "elements": [
                "draconicevolution:draconium_block@0"
            ]
        },
        {
            "x": 8,
            "y": -2,
            "z": 10,
            "elements": [
                "draconicevolution:draconium_block@0"
            ]
        },
        {
            "x": 0,
            "y": 6,
            "z": 12,
            "elements": [
                "draconicevolution:infused_obsidian@0"
            ]
        },
        {
            "x": -1,
            "y": -2,
            "z": 2,
            "elements": [
                "draconicevolution:draconium_block@0"
            ]
        },
        {
            "x": -5,
            "y": -2,
            "z": 8,
            "elements": [
                "draconicevolution:draconium_block@0"
            ]
        },
        {
            "x": -2,
            "y": 12,
            "z": 3,
            "elements": [
                "draconicevolution:infused_obsidian@0"
            ]
        },
        {
            "x": 2,
            "y": 2,
            "z": 7,
            "elements": [
                "draconicevolution:infused_obsidian@0"
            ]
        },
        {
            "x": 0,
            "y": -2,
            "z": -2,
            "elements": [
                "draconicevolution:draconium_block@0"
            ]
        },
        {
            "x": 8,
            "y": -2,
            "z": 5,
            "elements": [
                "draconicevolution:draconium_block@0"
            ]
        },
        {
            "x": 6,
            "y": -2,
            "z": 1,
            "elements": [
                "draconicevolution:draconium_block@0"
            ]
        },
        {
            "x": 4,
            "y": -2,
            "z": 7,
            "elements": [
                "draconicevolution:draconium_block@0"
            ]
        },
        {
            "x": -5,
            "y": -2,
            "z": -1,
            "elements": [
                "draconicevolution:draconium_block@0"
            ]
        },
        {
            "x": 5,
            "y": -2,
            "z": 13,
            "elements": [
                "draconicevolution:draconium_block@0"
            ]
        },
        {
            "x": 0,
            "y": 7,
            "z": 12,
            "elements": [
                "draconicevolution:infused_obsidian@0"
            ]
        },
        {
            "x": 3,
            "y": -2,
            "z": 1,
            "elements": [
                "draconicevolution:draconium_block@0"
            ]
        },
        {
            "x": -8,
            "y": -2,
            "z": 3,
            "elements": [
                "draconicevolution:draconium_block@0"
            ]
        },
        {
            "x": -7,
            "y": -2,
            "z": 9,
            "elements": [
                "draconicevolution:draconium_block@0"
            ]
        },
        {
            "x": -2,
            "y": -2,
            "z": 2,
            "elements": [
                "draconicevolution:draconium_block@0"
            ]
        },
        {
            "x": -2,
            "y": 5,
            "z": 2,
            "elements": [
                "mekanism:basicblock@10"
            ]
        },
        {
            "x": 0,
            "y": 8,
            "z": 12,
            "elements": [
                "draconicevolution:flow_gate@2"
            ]
        },
        {
            "x": -4,
            "y": -2,
            "z": 8,
            "elements": [
                "draconicevolution:draconium_block@0"
            ]
        },
        {
            "x": 3,
            "y": -2,
            "z": -2,
            "elements": [
                "draconicevolution:draconium_block@0"
            ]
        },
        {
            "x": 4,
            "y": -2,
            "z": -1,
            "elements": [
                "draconicevolution:draconium_block@0"
            ]
        },
        {
            "x": 5,
            "y": 1,
            "z": 6,
            "elements": [
                "chisel:blockinvar@6"
            ]
        },
        {
            "x": 7,
            "y": -2,
            "z": 7,
            "elements": [
                "draconicevolution:draconium_block@0"
            ]
        },
        {
            "x": 0,
            "y": 9,
            "z": 12,
            "elements": [
                "draconicevolution:infused_obsidian@0"
            ]
        },
        {
            "x": -1,
            "y": 13,
            "z": 3,
            "elements": [
                "draconicevolution:infused_obsidian@0"
            ]
        },
        {
            "x": 1,
            "y": -2,
            "z": 2,
            "elements": [
                "draconicevolution:draconium_block@0"
            ]
        },
        {
            "x": 2,
            "y": -2,
            "z": 13,
            "elements": [
                "draconicevolution:draconium_block@0"
            ]
        },
        {
            "x": -5,
            "y": -2,
            "z": 4,
            "elements": [
                "draconicevolution:draconium_block@0"
            ]
        },
        {
            "x": -2,
            "y": 10,
            "z": 1,
            "elements": [
                "mekanism:basicblock@10"
            ]
        },
        {
            "x": 4,
            "y": -2,
            "z": 6,
            "elements": [
                "draconicevolution:draconium_block@0"
            ]
        },
        {
            "x": -2,
            "y": -2,
            "z": -2,
            "elements": [
                "draconicevolution:draconium_block@0"
            ]
        },
        {
            "x": -3,
            "y": -2,
            "z": 8,
            "elements": [
                "draconicevolution:draconium_block@0"
            ]
        },
        {
            "x": 7,
            "y": -2,
            "z": 3,
            "elements": [
                "draconicevolution:draconium_block@0"
            ]
        },
        {
            "x": 5,
            "y": -2,
            "z": 10,
            "elements": [
                "draconicevolution:draconium_block@0"
            ]
        },
        {
            "x": -1,
            "y": 5,
            "z": 1,
            "elements": [
                "mekanism:basicblock@10"
            ]
        },
        {
            "x": -3,
            "y": -2,
            "z": 1,
            "elements": [
                "draconicevolution:draconium_block@0"
            ]
        },
        {
            "x": -2,
            "y": 14,
            "z": 5,
            "elements": [
                "draconicevolution:infused_obsidian@0"
            ]
        },
        {
            "x": -6,
            "y": 2,
            "z": 6,
            "elements": [
                "chisel:blockinvar@6"
            ]
        },
        {
            "x": -6,
            "y": 9,
            "z": 6,
            "elements": [
                "draconicevolution:infused_obsidian@0"
            ]
        },
        {
            "x": 4,
            "y": -2,
            "z": 10,
            "elements": [
                "draconicevolution:draconium_block@0"
            ]
        },
        {
            "x": -1,
            "y": -2,
            "z": 6,
            "elements": [
                "draconicevolution:draconium_block@0"
            ]
        },
        {
            "x": -6,
            "y": 8,
            "z": 6,
            "elements": [
                "fluxnetworks:fluxblock@0"
            ]
        },
        {
            "x": 1,
            "y": -2,
            "z": 11,
            "elements": [
                "draconicevolution:draconium_block@0"
            ]
        },
        {
            "x": -7,
            "y": -2,
            "z": 7,
            "elements": [
                "draconicevolution:draconium_block@0"
            ]
        },
        {
            "x": -6,
            "y": 3,
            "z": 6,
            "elements": [
                "chisel:blockinvar@6"
            ]
        },
        {
            "x": -5,
            "y": -2,
            "z": 14,
            "elements": [
                "draconicevolution:draconium_block@0"
            ]
        },
        {
            "x": 2,
            "y": -2,
            "z": -1,
            "elements": [
                "draconicevolution:draconium_block@0"
            ]
        },
        {
            "x": 2,
            "y": -2,
            "z": 1,
            "elements": [
                "draconicevolution:draconium_block@0"
            ]
        },
        {
            "x": -6,
            "y": 4,
            "z": 6,
            "elements": [
                "chisel:blockinvar@6"
            ]
        },
        {
            "x": 3,
            "y": -2,
            "z": 2,
            "elements": [
                "draconicevolution:draconium_block@0"
            ]
        },
        {
            "x": 2,
            "y": -2,
            "z": 6,
            "elements": [
                "draconicevolution:draconium_block@0"
            ]
        },
        {
            "x": -6,
            "y": 7,
            "z": 6,
            "elements": [
                "draconicevolution:infused_obsidian@0"
            ]
        },
        {
            "x": -7,
            "y": -2,
            "z": 0,
            "elements": [
                "draconicevolution:draconium_block@0"
            ]
        },
        {
            "x": 4,
            "y": -2,
            "z": -2,
            "elements": [
                "draconicevolution:draconium_block@0"
            ]
        },
        {
            "x": -3,
            "y": 3,
            "z": 6,
            "elements": [
                "draconicevolution:infused_obsidian@0"
            ]
        },
        {
            "x": -6,
            "y": 5,
            "z": 6,
            "elements": [
                "chisel:blockinvar@6"
            ]
        },
        {
            "x": -2,
            "y": -2,
            "z": 11,
            "elements": [
                "draconicevolution:draconium_block@0"
            ]
        },
        {
            "x": 1,
            "y": -2,
            "z": 13,
            "elements": [
                "draconicevolution:draconium_block@0"
            ]
        },
        {
            "x": -1,
            "y": -2,
            "z": -1,
            "elements": [
                "draconicevolution:draconium_block@0"
            ]
        },
        {
            "x": 0,
            "y": 1,
            "z": 1,
            "elements": [
                "chisel:blockinvar@6"
            ]
        },
        {
            "x": -6,
            "y": -2,
            "z": 14,
            "elements": [
                "draconicevolution:draconium_block@0"
            ]
        },
        {
            "x": 8,
            "y": -2,
            "z": 0,
            "elements": [
                "draconicevolution:draconium_block@0"
            ]
        },
        {
            "x": 0,
            "y": -2,
            "z": 7,
            "elements": [
                "draconicevolution:draconium_block@0"
            ]
        },
        {
            "x": 0,
            "y": 2,
            "z": 6,
            "elements": [
                "draconicevolution:flow_gate@5"
            ]
        },
        {
            "x": -5,
            "y": 11,
            "z": 6,
            "elements": [
                "draconicevolution:infused_obsidian@0"
            ]
        },
        {
            "x": 0,
            "y": -1,
            "z": 12,
            "elements": [
                "chisel:blockinvar@6"
            ]
        },
        {
            "x": -1,
            "y": -2,
            "z": 1,
            "elements": [
                "draconicevolution:draconium_block@0"
            ]
        },
        {
            "x": -8,
            "y": -2,
            "z": 8,
            "elements": [
                "draconicevolution:draconium_block@0"
            ]
        },
        {
            "x": -6,
            "y": -2,
            "z": 2,
            "elements": [
                "draconicevolution:draconium_block@0"
            ]
        },
        {
            "x": 1,
            "y": 2,
            "z": 7,
            "elements": [
                "draconicevolution:infused_obsidian@0"
            ]
        },
        {
            "x": 0,
            "y": 11,
            "z": 0,
            "elements": [
                "botania:quartzstairsred@2"
            ]
        },
        {
            "x": -3,
            "y": -2,
            "z": 12,
            "elements": [
                "draconicevolution:draconium_block@0"
            ]
        },
        {
            "x": 0,
            "y": 3,
            "z": 6,
            "elements": [
                "draconicevolution:reactor_component@1"
            ]
        },
        {
            "x": 3,
            "y": -2,
            "z": 7,
            "elements": [
                "draconicevolution:draconium_block@0"
            ]
        },
        {
            "x": 0,
            "y": -2,
            "z": 12,
            "elements": [
                "draconicevolution:draconium_block@0"
            ]
        },
        {
            "x": 7,
            "y": -2,
            "z": -2,
            "elements": [
                "draconicevolution:draconium_block@0"
            ]
        },
        {
            "x": -2,
            "y": 2,
            "z": 7,
            "elements": [
                "draconicevolution:infused_obsidian@0"
            ]
        },
        {
            "x": -2,
            "y": -2,
            "z": 13,
            "elements": [
                "draconicevolution:draconium_block@0"
            ]
        },
        {
            "x": -7,
            "y": -2,
            "z": 14,
            "elements": [
                "draconicevolution:draconium_block@0"
            ]
        },
        {
            "x": 7,
            "y": -2,
            "z": 11,
            "elements": [
                "draconicevolution:draconium_block@0"
            ]
        },
        {
            "x": 0,
            "y": -2,
            "z": -1,
            "elements": [
                "draconicevolution:draconium_block@0"
            ]
        },
        {
            "x": -7,
            "y": -2,
            "z": 6,
            "elements": [
                "draconicevolution:draconium_block@0"
            ]
        },
        {
            "x": -6,
            "y": 11,
            "z": 6,
            "elements": [
                "botania:quartzstairsred@0"
            ]
        },
        {
            "x": 0,
            "y": -2,
            "z": 1,
            "elements": [
                "draconicevolution:draconium_block@0"
            ]
        },
        {
            "x": -3,
            "y": -2,
            "z": 2,
            "elements": [
                "draconicevolution:draconium_block@0"
            ]
        },
        {
            "x": 0,
            "y": 9,
            "z": 0,
            "elements": [
                "draconicevolution:infused_obsidian@0"
            ]
        },
        {
            "x": -6,
            "y": -2,
            "z": 12,
            "elements": [
                "draconicevolution:draconium_block@0"
            ]
        },
        {
            "x": -5,
            "y": 12,
            "z": 6,
            "elements": [
                "botania:quartzstairsred@0"
            ]
        },
        {
            "x": -3,
            "y": 7,
            "z": 1,
            "elements": [
                "mekanism:basicblock@10"
            ]
        },
        {
            "x": -8,
            "y": -2,
            "z": 11,
            "elements": [
                "draconicevolution:draconium_block@0"
            ]
        },
        {
            "x": -6,
            "y": 10,
            "z": 6,
            "elements": [
                "draconicevolution:infused_obsidian@0"
            ]
        },
        {
            "x": -6,
            "y": 0,
            "z": 6,
            "elements": [
                "chisel:blockinvar@6"
            ]
        },
        {
            "x": 1,
            "y": -2,
            "z": 10,
            "elements": [
                "draconicevolution:draconium_block@0"
            ]
        },
        {
            "x": -6,
            "y": 1,
            "z": 6,
            "elements": [
                "chisel:blockinvar@6"
            ]
        },
        {
            "x": 1,
            "y": -2,
            "z": -1,
            "elements": [
                "draconicevolution:draconium_block@0"
            ]
        },
        {
            "x": -4,
            "y": -2,
            "z": 14,
            "elements": [
                "draconicevolution:draconium_block@0"
            ]
        },
        {
            "x": -8,
            "y": -2,
            "z": 6,
            "elements": [
                "draconicevolution:draconium_block@0"
            ]
        },
        {
            "x": 0,
            "y": 10,
            "z": 0,
            "elements": [
                "draconicevolution:infused_obsidian@0"
            ]
        },
        {
            "x": 0,
            "y": 7,
            "z": 0,
            "elements": [
                "draconicevolution:infused_obsidian@0"
            ]
        },
        {
            "x": -1,
            "y": -2,
            "z": 14,
            "elements": [
                "draconicevolution:draconium_block@0"
            ]
        },
        {
            "x": 1,
            "y": -2,
            "z": 1,
            "elements": [
                "draconicevolution:draconium_block@0"
            ]
        },
        {
            "x": -7,
            "y": -2,
            "z": -2,
            "elements": [
                "draconicevolution:draconium_block@0"
            ]
        },
        {
            "x": -3,
            "y": 9,
            "z": 1,
            "elements": [
                "mekanism:basicblock@10"
            ]
        },
        {
            "x": -4,
            "y": -2,
            "z": 0,
            "elements": [
                "draconicevolution:draconium_block@0"
            ]
        },
        {
            "x": 7,
            "y": -2,
            "z": 9,
            "elements": [
                "draconicevolution:draconium_block@0"
            ]
        },
        {
            "x": -5,
            "y": 11,
            "z": 5,
            "elements": [
                "mekanism:basicblock@10"
            ]
        },
        {
            "x": -5,
            "y": -2,
            "z": 12,
            "elements": [
                "draconicevolution:draconium_block@0"
            ]
        },
        {
            "x": 1,
            "y": 2,
            "z": 5,
            "elements": [
                "draconicevolution:infused_obsidian@0"
            ]
        },
        {
            "x": -5,
            "y": -2,
            "z": 6,
            "elements": [
                "draconicevolution:draconium_block@0"
            ]
        },
        {
            "x": -2,
            "y": 2,
            "z": 6,
            "elements": [
                "draconicevolution:infused_obsidian@0"
            ]
        },
        {
            "x": 1,
            "y": -2,
            "z": 8,
            "elements": [
                "draconicevolution:draconium_block@0"
            ]
        },
        {
            "x": -8,
            "y": -2,
            "z": 13,
            "elements": [
                "draconicevolution:draconium_block@0"
            ]
        },
        {
            "x": 6,
            "y": -2,
            "z": -1,
            "elements": [
                "draconicevolution:draconium_block@0"
            ]
        },
        {
            "x": 0,
            "y": 8,
            "z": 0,
            "elements": [
                "draconicevolution:flow_gate@1"
            ]
        },
        {
            "x": 8,
            "y": -2,
            "z": 2,
            "elements": [
                "draconicevolution:draconium_block@0"
            ]
        },
        {
            "x": -3,
            "y": -2,
            "z": 7,
            "elements": [
                "draconicevolution:draconium_block@0"
            ]
        },
        {
            "x": -3,
            "y": 8,
            "z": 1,
            "elements": [
                "draconicevolution:infused_obsidian@0"
            ]
        },
        {
            "x": -2,
            "y": -2,
            "z": 14,
            "elements": [
                "draconicevolution:draconium_block@0"
            ]
        },
        {
            "x": -8,
            "y": -2,
            "z": -2,
            "elements": [
                "draconicevolution:draconium_block@0"
            ]
        },
        {
            "x": 0,
            "y": -2,
            "z": 5,
            "elements": [
                "draconicevolution:draconium_block@0"
            ]
        },
        {
            "x": -2,
            "y": -2,
            "z": 1,
            "elements": [
                "draconicevolution:draconium_block@0"
            ]
        },
        {
            "x": 8,
            "y": -2,
            "z": 9,
            "elements": [
                "draconicevolution:draconium_block@0"
            ]
        },
        {
            "x": 0,
            "y": 13,
            "z": 9,
            "elements": [
                "draconicevolution:infused_obsidian@0"
            ]
        },
        {
            "x": 0,
            "y": 13,
            "z": 2,
            "elements": [
                "botania:quartzstairsred@2"
            ]
        },
        {
            "x": -4,
            "y": -2,
            "z": 12,
            "elements": [
                "draconicevolution:draconium_block@0"
            ]
        },
        {
            "x": 0,
            "y": 6,
            "z": 0,
            "elements": [
                "draconicevolution:infused_obsidian@0"
            ]
        },
        {
            "x": 3,
            "y": -2,
            "z": -1,
            "elements": [
                "draconicevolution:draconium_block@0"
            ]
        },
        {
            "x": 6,
            "y": -2,
            "z": 8,
            "elements": [
                "draconicevolution:draconium_block@0"
            ]
        },
        {
            "x": -2,
            "y": -2,
            "z": 6,
            "elements": [
                "draconicevolution:draconium_block@0"
            ]
        },
        {
            "x": 7,
            "y": -2,
            "z": 10,
            "elements": [
                "draconicevolution:draconium_block@0"
            ]
        },
        {
            "x": -3,
            "y": -2,
            "z": 13,
            "elements": [
                "draconicevolution:draconium_block@0"
            ]
        },
        {
            "x": 0,
            "y": 11,
            "z": 1,
            "elements": [
                "draconicevolution:infused_obsidian@0"
            ]
        },
        {
            "x": -4,
            "y": 0,
            "z": 6,
            "elements": [
                "chisel:blockinvar@6"
            ]
        },
        {
            "x": -4,
            "y": -2,
            "z": 7,
            "elements": [
                "draconicevolution:draconium_block@0"
            ]
        },
        {
            "x": -5,
            "y": -2,
            "z": 1,
            "elements": [
                "draconicevolution:draconium_block@0"
            ]
        },
        {
            "x": 0,
            "y": 14,
            "z": 9,
            "elements": [
                "botania:quartzstairsred@3"
            ]
        },
        {
            "x": 0,
            "y": 12,
            "z": 2,
            "elements": [
                "draconicevolution:infused_obsidian@0"
            ]
        },
        {
            "x": 0,
            "y": 8,
            "z": 1,
            "elements": [
                "draconicevolution:reactor_component@0"
            ]
        },
        {
            "x": 1,
            "y": 2,
            "z": 8,
            "elements": [
                "draconicevolution:infused_obsidian@0"
            ]
        },
        {
            "x": 0,
            "y": 5,
            "z": 0,
            "elements": [
                "chisel:blockinvar@6"
            ]
        },
        {
            "x": -5,
            "y": 8,
            "z": 6,
            "elements": [
                "draconicevolution:reactor_component@0"
            ]
        },
        {
            "x": 2,
            "y": -2,
            "z": 0,
            "elements": [
                "draconicevolution:draconium_block@0"
            ]
        },
        {
            "x": -6,
            "y": 6,
            "z": 6,
            "elements": [
                "draconicevolution:infused_obsidian@0"
            ]
        },
        {
            "x": -3,
            "y": -1,
            "z": 6,
            "elements": [
                "chisel:blockinvar@6"
            ]
        },
        {
            "x": 0,
            "y": 4,
            "z": 0,
            "elements": [
                "chisel:blockinvar@6"
            ]
        },
        {
            "x": -5,
            "y": -2,
            "z": -2,
            "elements": [
                "draconicevolution:draconium_block@0"
            ]
        },
        {
            "x": -7,
            "y": -2,
            "z": 12,
            "elements": [
                "draconicevolution:draconium_block@0"
            ]
        },
        {
            "x": 3,
            "y": -2,
            "z": 5,
            "elements": [
                "draconicevolution:draconium_block@0"
            ]
        },
        {
            "x": 3,
            "y": -2,
            "z": 8,
            "elements": [
                "draconicevolution:draconium_block@0"
            ]
        },
        {
            "x": -3,
            "y": -2,
            "z": 6,
            "elements": [
                "draconicevolution:draconium_block@0"
            ]
        },
        {
            "x": -5,
            "y": -1,
            "z": 1,
            "elements": [
                "modularmachinery:blockoutputbus",
                "modularmachinery:blockmeitemoutputbus"
            ]
        },
        {
            "x": -5,
            "y": 5,
            "z": 6,
            "elements": [
                "draconicevolution:infused_obsidian@0"
            ]
        },
        {
            "x": -6,
            "y": -2,
            "z": 13,
            "elements": [
                "draconicevolution:draconium_block@0"
            ]
        },
        {
            "x": 0,
            "y": 3,
            "z": 0,
            "elements": [
                "chisel:blockinvar@6"
            ]
        },
        {
            "x": -4,
            "y": -2,
            "z": -1,
            "elements": [
                "draconicevolution:draconium_block@0"
            ]
        },
        {
            "x": 6,
            "y": -2,
            "z": 2,
            "elements": [
                "draconicevolution:draconium_block@0"
            ]
        },
        {
            "x": 5,
            "y": -2,
            "z": 0,
            "elements": [
                "draconicevolution:draconium_block@0"
            ]
        },
        {
            "x": -1,
            "y": -2,
            "z": 7,
            "elements": [
                "draconicevolution:draconium_block@0"
            ]
        },
        {
            "x": 4,
            "y": -2,
            "z": 1,
            "elements": [
                "draconicevolution:draconium_block@0"
            ]
        },
        {
            "x": -4,
            "y": 4,
            "z": 6,
            "elements": [
                "draconicevolution:infused_obsidian@0"
            ]
        },
        {
            "x": 0,
            "y": 5,
            "z": 1,
            "elements": [
                "draconicevolution:infused_obsidian@0"
            ]
        },
        {
            "x": 0,
            "y": 2,
            "z": 0,
            "elements": [
                "chisel:blockinvar@6"
            ]
        },
        {
            "x": -1,
            "y": -2,
            "z": 0,
            "elements": [
                "draconicevolution:draconium_block@0"
            ]
        },
        {
            "x": 6,
            "y": -2,
            "z": 5,
            "elements": [
                "draconicevolution:draconium_block@0"
            ]
        },
        {
            "x": -2,
            "y": -2,
            "z": 12,
            "elements": [
                "draconicevolution:draconium_block@0"
            ]
        },
        {
            "x": 0,
            "y": 1,
            "z": 0,
            "elements": [
                "chisel:blockinvar@6",
                "modularmachinery:blockparallelcontroller"
            ]
        },
        {
            "x": -4,
            "y": -2,
            "z": 6,
            "elements": [
                "draconicevolution:draconium_block@0"
            ]
        },
        {
            "x": 4,
            "y": -2,
            "z": 8,
            "elements": [
                "draconicevolution:draconium_block@0"
            ]
        },
        {
            "x": -5,
            "y": -2,
            "z": 13,
            "elements": [
                "draconicevolution:draconium_block@0"
            ]
        },
        {
            "x": -6,
            "y": -2,
            "z": 7,
            "elements": [
                "draconicevolution:draconium_block@0"
            ]
        },
        {
            "x": -3,
            "y": -2,
            "z": -1,
            "elements": [
                "draconicevolution:draconium_block@0"
            ]
        },
        {
            "x": -8,
            "y": -2,
            "z": 14,
            "elements": [
                "draconicevolution:draconium_block@0"
            ]
        },
        {
            "x": 4,
            "y": -2,
            "z": 11,
            "elements": [
                "draconicevolution:draconium_block@0"
            ]
        }
    ]}