{
    "registryname": "TMSR",
    "localizedname": "钍基熔盐反应堆",
    "parts": [
        {
            "x": 0,
            "y": 0,
            "z": 0,

            "elements": [
                "modularmachinery:tmsr_factory_controller@2"
            ]
        },
        {
            "x": -2,
            "y": -1,
            "z": 12,
            "elements": [
                "chisel:technical@1"
            ]
        },
        {
            "x": -7,
            "y": -1,
            "z": 11,
            "elements": [
                "chisel:technical@1"
            ]
        },
        {
            "x": -6,
            "y": 0,
            "z": 10,
            "elements": [
                "chisel:concrete_black@7"
            ]
        },
        {
            "x": -17,
            "y": -1,
            "z": 12,
            "elements": [
                "chisel:technical@1"
            ]
        },
        {
            "x": -14,
            "y": 1,
            "z": 9,
            "elements": [
                "chisel:technical@5"
            ]
        },
        {
            "x": -13,
            "y": -1,
            "z": 4,
            "elements": [
                "chisel:technical@1"
            ]
        },
        {
            "x": -13,
            "y": 3,
            "z": 9,
            "elements": [
                "chisel:factory1@0"
            ]
        },
        {
            "x": 1,
            "y": 0,
            "z": 0,

            "elements": [
                "modularmachinery:blocksmartinterface@0"
            ]
        },
        {
            "x": -3,
            "y": 8,
            "z": 7,
            "elements": [
                "chisel:concrete_black@7"
            ]
        },
        {
            "x": -7,
            "y": 6,
            "z": 10,
            "elements": [
                "chisel:concrete_black@7"
            ]
        },
        {
            "x": -10,
            "y": 3,
            "z": 12,
            "elements": [
                "chisel:concrete_black@7"
            ]
        },
        {
            "x": -12,
            "y": -1,
            "z": 9,
            "elements": [
                "chisel:technical@1"
            ]
        },
        {
            "x": -3,
            "y": 7,
            "z": 14,
            "elements": [
                "chisel:concrete_black@7"
            ]
        },
        {
            "x": -10,
            "y": 0,
            "z": 12,
            "elements": [
                "chisel:technicalnew@2"
            ]
        },
        {
            "x": -5,
            "y": 9,
            "z": 11,
            "elements": [
                "chisel:technicalnew@2"
            ]
        },
        {
            "x": -10,
            "y": -1,
            "z": 11,
            "elements": [
                "chisel:technical@1"
            ]
        },
        {
            "x": 1,
            "y": 5,
            "z": 9,
            "elements": [
                "chisel:concrete_black@7"
            ]
        },
        {
            "x": -2,
            "y": 7,
            "z": 11,
            "elements": [
                "nuclearcraft:ingot_block@8"
            ]
        },
        {
            "x": -14,
            "y": 3,
            "z": 9,
            "elements": [
                "chisel:factory@10"
            ]
        },
        {
            "x": -13,
            "y": 1,
            "z": 9,

            "elements": [
                "mekanism:basicblock@10"
            ]
        },
        {
            "x": -5,
            "y": 0,
            "z": 10,
            "elements": [
                "chisel:concrete_black@7"
            ]
        },
        {
            "x": -3,
            "y": 8,
            "z": 14,
            "elements": [
                "chisel:factory@6"
            ]
        },
        {
            "x": -10,
            "y": 1,
            "z": 12,
            "elements": [
                "chisel:technical@3"
            ]
        },
        {
            "x": 3,
            "y": -1,
            "z": 9,
            "elements": [
                "chisel:technical@1"
            ]
        },
        {
            "x": -8,
            "y": -1,
            "z": 12,
            "elements": [
                "chisel:technical@1"
            ]
        },
        {
            "x": 0,
            "y": 3,
            "z": 14,
            "elements": [
                "chisel:concrete_black@7"
            ]
        },
        {
            "x": -2,
            "y": 9,
            "z": 9,
            "elements": [
                "chisel:technical@10"
            ]
        },
        {
            "x": -13,
            "y": 3,
            "z": 12,
            "elements": [
                "chisel:factory1@0"
            ]
        },
        {
            "x": -7,
            "y": 4,
            "z": 10,
            "elements": [
                "chisel:concrete_black@7"
            ]
        },
        {
            "x": -1,
            "y": -1,
            "z": 11,
            "elements": [
                "chisel:technical@1"
            ]
        },
        {
            "x": -9,
            "y": 1,
            "z": 11,
            "elements": [
                "chisel:concrete_black@7"
            ]
        },
        {
            "x": -7,
            "y": 2,
            "z": 10,
            "elements": [
                "chisel:concrete_black@7"
            ]
        },
        {
            "x": -4,
            "y": 0,
            "z": 10,
            "elements": [
                "chisel:concrete_black@7"
            ]
        },
        {
            "x": -11,
            "y": -1,
            "z": 12,
            "elements": [
                "chisel:technical@1"
            ]
        },
        {
            "x": -1,
            "y": 0,
            "z": 0,

            "elements": [
                "modularmachinery:blocksmartinterface@0"
            ]
        },
        {
            "x": -11,
            "y": 3,
            "z": 9,
            "elements": [
                "chisel:factory1@0"
            ]
        },
        {
            "x": -9,
            "y": 3,
            "z": 11,
            "elements": [
                "chisel:factory1@0"
            ]
        },
        {
            "x": -15,
            "y": 0,
            "z": 8,
            "elements": [
                "chisel:technicalnew@2"
            ]
        },
        {
            "x": 0,
            "y": -1,
            "z": 11,
            "elements": [
                "chisel:technical@1"
            ]
        },
        {
            "x": -7,
            "y": -1,
            "z": 1,
            "elements": [
                "chisel:technical@1"
            ]
        },
        {
            "x": -7,
            "y": 0,
            "z": 10,
            "elements": [
                "chisel:factory@6"
            ]
        },
        {
            "x": -14,
            "y": -1,
            "z": 9,
            "elements": [
                "chisel:technical@1"
            ]
        },
        {
            "x": -16,
            "y": -1,
            "z": 8,
            "elements": [
                "chisel:technical@1"
            ]
        },
        {
            "x": -11,
            "y": 1,
            "z": 9,
            "elements": [
                "chisel:concrete_black@7"
            ]
        },
        {
            "x": -11,
            "y": -1,
            "z": 9,
            "elements": [
                "chisel:technical@1"
            ]
        },
        {
            "x": -14,
            "y": -1,
            "z": 12,
            "elements": [
                "chisel:technical@1"
            ]
        },
        {
            "x": -10,
            "y": -1,
            "z": 4,
            "elements": [
                "chisel:technical@1"
            ]
        },
        {
            "x": -7,
            "y": 8,
            "z": 10,
            "elements": [
                "chisel:factory@6"
            ]
        },
        {
            "x": -3,
            "y": -1,
            "z": 11,
            "elements": [
                "chisel:technical@1"
            ]
        },
        {
            "x": 2,
            "y": -1,
            "z": 4,
            "elements": [
                "chisel:technical@1"
            ]
        },
        {
            "x": -13,
            "y": 0,
            "z": 12,
            "elements": [
                "chisel:technicalnew@2"
            ]
        },
        {
            "x": -10,
            "y": -1,
            "z": 1,
            "elements": [
                "chisel:technical@1"
            ]
        },
        {
            "x": 0,
            "y": 9,
            "z": 7,
            "elements": [
                "chisel:technical@11"
            ]
        },
        {
            "x": -10,
            "y": 0,
            "z": 10,
            "elements": [
                "chisel:technicalnew@2"
            ]
        },
        {
            "x": -9,
            "y": 2,
            "z": 10,
            "elements": [
                "chisel:concrete_black@7"
            ]
        },
        {
            "x": -1,
            "y": -1,
            "z": 4,
            "elements": [
                "chisel:technical@1"
            ]
        },
        {
            "x": 1,
            "y": 9,
            "z": 9,
            "elements": [
                "chisel:technical@3"
            ]
        },
        {
            "x": -1,
            "y": 7,
            "z": 12,
            "elements": [
                "nuclearcraft:ingot_block@9"
            ]
        },
        {
            "x": 0,
            "y": -1,
            "z": 9,
            "elements": [
                "chisel:technical@1"
            ]
        },
        {
            "x": 0,
            "y": 8,
            "z": 7,
            "elements": [
                "chisel:concrete_black@7"
            ]
        },
        {
            "x": -13,
            "y": 1,
            "z": 12,
            "elements": [
                "chisel:factory1@0"
            ]
        },
        {
            "x": -16,
            "y": -1,
            "z": 2,
            "elements": [
                "chisel:technical@1"
            ]
        },
        {
            "x": -9,
            "y": 0,
            "z": 10,
            "elements": [
                "chisel:technicalnew@2"
            ]
        },
        {
            "x": -6,
            "y": -1,
            "z": 11,
            "elements": [
                "chisel:technical@1"
            ]
        },
        {
            "x": -13,
            "y": 2,
            "z": 12,
            "elements": [
                "chisel:factory1@0"
            ]
        },
        {
            "x": 2,
            "y": 0,
            "z": 5,
            "elements": [
                "chisel:technical@11"
            ]
        },
        {
            "x": 2,
            "y": 2,
            "z": 5,
            "elements": [
                "chisel:technical@11"
            ]
        },
        {
            "x": -13,
            "y": -1,
            "z": 1,
            "elements": [
                "chisel:technical@1"
            ]
        },
        {
            "x": 0,
            "y": 7,
            "z": 7,
            "elements": [
                "chisel:concrete_black@7"
            ]
        },
        {
            "x": -10,
            "y": 2,
            "z": 10,
            "elements": [
                "chisel:technical@5"
            ]
        },
        {
            "x": -4,
            "y": -1,
            "z": 4,
            "elements": [
                "chisel:technical@1"
            ]
        },
        {
            "x": -17,
            "y": -1,
            "z": 13,
            "elements": [
                "chisel:technical@1"
            ]
        },
        {
            "x": 1,
            "y": 3,
            "z": 9,
            "elements": [
                "chisel:concrete_black@7"
            ]
        },
        {
            "x": -2,
            "y": 0,
            "z": 15,

            "elements": [
                "modularmachinery:blockfluidoutputhatch",
                "modularmachinery:blockmefluidoutputbus"
            ]
        },
        {
            "x": -5,
            "y": -1,
            "z": 11,
            "elements": [
                "chisel:technical@1"
            ]
        },
        {
            "x": -19,
            "y": -1,
            "z": 8,
            "elements": [
                "chisel:technical@1"
            ]
        },
        {
            "x": 0,
            "y": 0,
            "z": 10,
            "elements": [
                "chisel:concrete_black@7"
            ]
        },
        {
            "x": -7,
            "y": -1,
            "z": 4,
            "elements": [
                "chisel:technical@1"
            ]
        },
        {
            "x": 0,
            "y": 8,
            "z": 6,
            "elements": [
                "chisel:factory@6"
            ]
        },
        {
            "x": -3,
            "y": 6,
            "z": 10,
            "elements": [
                "nuclearcraft:ingot_block@9"
            ]
        },
        {
            "x": -5,
            "y": 9,
            "z": 9,
            "elements": [
                "chisel:technicalnew@2"
            ]
        },
        {
            "x": -14,
            "y": -1,
            "z": 13,
            "elements": [
                "chisel:technical@1"
            ]
        },
        {
            "x": -6,
            "y": 8,
            "z": 10,
            "elements": [
                "chisel:concrete_black@7"
            ]
        },
        {
            "x": -19,
            "y": -1,
            "z": 1,
            "elements": [
                "chisel:technical@1"
            ]
        },
        {
            "x": 2,
            "y": -1,
            "z": 7,
            "elements": [
                "chisel:technical@1"
            ]
        },
        {
            "x": -3,
            "y": 0,
            "z": 15,
            "elements": [
                "chisel:technical@3"
            ]
        },
        {
            "x": 1,
            "y": -1,
            "z": 12,
            "elements": [
                "chisel:technical@1"
            ]
        },
        {
            "x": 1,
            "y": 1,
            "z": 9,
            "elements": [
                "chisel:concrete_black@7"
            ]
        },
        {
            "x": -2,
            "y": 7,
            "z": 9,
            "elements": [
                "nuclearcraft:ingot_block@8"
            ]
        },
        {
            "x": -4,
            "y": -1,
            "z": 11,
            "elements": [
                "chisel:technical@1"
            ]
        },
        {
            "x": 0,
            "y": 7,
            "z": 6,
            "elements": [
                "chisel:factory1@0"
            ]
        },
        {
            "x": -1,
            "y": 0,
            "z": 12,
            "elements": [
                "chisel:concrete_black@7"
            ]
        },
        {
            "x": -3,
            "y": 8,
            "z": 10,
            "elements": [
                "nuclearcraft:ingot_block@9"
            ]
        },
        {
            "x": -4,
            "y": -1,
            "z": 1,
            "elements": [
                "chisel:technical@1"
            ]
        },
        {
            "x": 1,
            "y": 7,
            "z": 9,
            "elements": [
                "chisel:concrete_black@7"
            ]
        },
        {
            "x": -3,
            "y": 0,
            "z": 10,
            "elements": [
                "chisel:concrete_black@7"
            ]
        },
        {
            "x": 0,
            "y": 6,
            "z": 6,
            "elements": [
                "chisel:concrete_black@7"
            ]
        },
        {
            "x": -19,
            "y": -1,
            "z": 2,
            "elements": [
                "chisel:technical@1"
            ]
        },
        {
            "x": -14,
            "y": 0,
            "z": 10,
            "elements": [
                "chisel:technicalnew@2"
            ]
        },
        {
            "x": 2,
            "y": -1,
            "z": 8,
            "elements": [
                "chisel:technical@1"
            ]
        },
        {
            "x": -17,
            "y": -1,
            "z": 6,
            "elements": [
                "chisel:technical@1"
            ]
        },
        {
            "x": -7,
            "y": 7,
            "z": 9,
            "elements": [
                "chisel:concrete_black@7"
            ]
        },
        {
            "x": -4,
            "y": -1,
            "z": 9,
            "elements": [
                "chisel:technical@1"
            ]
        },
        {
            "x": 0,
            "y": 8,
            "z": 10,
            "elements": [
                "chisel:concrete_black@7"
            ]
        },
        {
            "x": -15,
            "y": -1,
            "z": 11,
            "elements": [
                "chisel:technical@1"
            ]
        },
        {
            "x": -5,
            "y": -1,
            "z": 4,
            "elements": [
                "chisel:technical@1"
            ]
        },
        {
            "x": 3,
            "y": 0,
            "z": 8,

            "elements": [
                "modularmachinery:blockinputbus",
                "modularmachinery:blockmeiteminputbus"
            ]
        },
        {
            "x": -13,
            "y": 0,
            "z": 6,
            "elements": [
                "chisel:technical@3"
            ]
        },
        {
            "x": -6,
            "y": 8,
            "z": 8,
            "elements": [
                "chisel:concrete_black@7"
            ]
        },
        {
            "x": -7,
            "y": 5,
            "z": 9,
            "elements": [
                "chisel:concrete_black@7"
            ]
        },
        {
            "x": -14,
            "y": 2,
            "z": 10,
            "elements": [
                "chisel:technical@3"
            ]
        },
        {
            "x": -14,
            "y": -1,
            "z": 6,
            "elements": [
                "chisel:technical@1"
            ]
        },
        {
            "x": -16,
            "y": -1,
            "z": 7,
            "elements": [
                "chisel:technical@1"
            ]
        },
        {
            "x": -5,
            "y": -1,
            "z": 9,
            "elements": [
                "chisel:technical@1"
            ]
        },
        {
            "x": 1,
            "y": 0,
            "z": 3,
            "elements": [
                "chisel:technical@11"
            ]
        },
        {
            "x": -18,
            "y": -1,
            "z": 11,
            "elements": [
                "chisel:technical@1"
            ]
        },
        {
            "x": 1,
            "y": 4,
            "z": 10,
            "elements": [
                "chisel:concrete_black@7"
            ]
        },
        {
            "x": 3,
            "y": 0,
            "z": 10,

            "elements": [
                "modularmachinery:blockfluidinputhatch",
                "modularmachinery:blockmefluidinputbus"
            ]
        },
        {
            "x": -13,
            "y": -1,
            "z": 2,
            "elements": [
                "chisel:technical@1"
            ]
        },
        {
            "x": -16,
            "y": -1,
            "z": 1,
            "elements": [
                "chisel:technical@1"
            ]
        },
        {
            "x": -3,
            "y": 8,
            "z": 8,
            "elements": [
                "nuclearcraft:ingot_block@9"
            ]
        },
        {
            "x": -9,
            "y": 3,
            "z": 8,
            "elements": [
                "chisel:factory1@0"
            ]
        },
        {
            "x": 2,
            "y": 4,
            "z": 5,
            "elements": [
                "chisel:technical@11"
            ]
        },
        {
            "x": -6,
            "y": 0,
            "z": 8,
            "elements": [
                "chisel:concrete_black@7"
            ]
        },
        {
            "x": -9,
            "y": -1,
            "z": 11,
            "elements": [
                "chisel:technical@1"
            ]
        },
        {
            "x": -3,
            "y": 7,
            "z": 8,
            "elements": [
                "nuclearcraft:ingot_block@9"
            ]
        },
        {
            "x": -6,
            "y": -1,
            "z": 9,
            "elements": [
                "chisel:technical@1"
            ]
        },
        {
            "x": -2,
            "y": 8,
            "z": 10,
            "elements": [
                "chisel:concrete_black@7"
            ]
        },
        {
            "x": -17,
            "y": 1,
            "z": 11,
            "elements": [
                "chisel:technical@3"
            ]
        },
        {
            "x": -3,
            "y": -1,
            "z": 4,
            "elements": [
                "chisel:technical@1"
            ]
        },
        {
            "x": -13,
            "y": -1,
            "z": 7,
            "elements": [
                "chisel:technical@1"
            ]
        },
        {
            "x": -9,
            "y": 1,
            "z": 8,
            "elements": [
                "chisel:technical@3"
            ]
        },
        {
            "x": -7,
            "y": -1,
            "z": 8,
            "elements": [
                "chisel:technical@1"
            ]
        },
        {
            "x": 1,
            "y": 6,
            "z": 10,
            "elements": [
                "chisel:concrete_black@7"
            ]
        },
        {
            "x": 1,
            "y": 2,
            "z": 10,
            "elements": [
                "chisel:concrete_black@7"
            ]
        },
        {
            "x": 2,
            "y": 6,
            "z": 5,
            "elements": [
                "chisel:technical@11"
            ]
        },
        {
            "x": -1,
            "y": -1,
            "z": 8,
            "elements": [
                "chisel:technical@1"
            ]
        },
        {
            "x": 0,
            "y": 7,
            "z": 13,
            "elements": [
                "chisel:concrete_black@7"
            ]
        },
        {
            "x": -1,
            "y": 8,
            "z": 12,
            "elements": [
                "nuclearcraft:ingot_block@9"
            ]
        },
        {
            "x": -3,
            "y": -1,
            "z": 9,
            "elements": [
                "chisel:technical@1"
            ]
        },
        {
            "x": 0,
            "y": 8,
            "z": 13,
            "elements": [
                "chisel:concrete_black@7"
            ]
        },
        {
            "x": 1,
            "y": 0,
            "z": 10,
            "elements": [
                "chisel:factory@6"
            ]
        },
        {
            "x": 0,
            "y": 0,
            "z": 8,
            "elements": [
                "chisel:concrete_black@7"
            ]
        },
        {
            "x": -9,
            "y": 2,
            "z": 8,
            "elements": [
                "chisel:concrete_black@7"
            ]
        },
        {
            "x": -2,
            "y": -1,
            "z": 4,
            "elements": [
                "chisel:technical@1"
            ]
        },
        {
            "x": 1,
            "y": 8,
            "z": 10,
            "elements": [
                "chisel:factory@6"
            ]
        },
        {
            "x": -1,
            "y": 9,
            "z": 12,
            "elements": [
                "chisel:technical@10"
            ]
        },
        {
            "x": 2,
            "y": 8,
            "z": 5,
            "elements": [
                "chisel:technical@11"
            ]
        },
        {
            "x": -4,
            "y": 0,
            "z": 15,

            "elements": [
                "modularmachinery:blockfluidoutputhatch",
                "modularmachinery:blockmefluidoutputbus"
            ]
        },
        {
            "x": 0,
            "y": 7,
            "z": 14,
            "elements": [
                "chisel:factory1@0"
            ]
        },
        {
            "x": -11,
            "y": 1,
            "z": 11,
            "elements": [
                "chisel:concrete_black@7"
            ]
        },
        {
            "x": -15,
            "y": 2,
            "z": 8,
            "elements": [
                "chisel:factory1@0"
            ]
        },
        {
            "x": 0,
            "y": 0,
            "z": 3,
            "elements": [
                "chisel:technical@11"
            ]
        },
        {
            "x": -10,
            "y": 1,
            "z": 9,
            "elements": [
                "chisel:technical@3"
            ]
        },
        {
            "x": -13,
            "y": -1,
            "z": 8,
            "elements": [
                "chisel:technical@1"
            ]
        },
        {
            "x": -8,
            "y": -1,
            "z": 9,
            "elements": [
                "chisel:technical@1"
            ]
        },
        {
            "x": -2,
            "y": 0,
            "z": 10,
            "elements": [
                "chisel:concrete_black@7"
            ]
        },
        {
            "x": -15,
            "y": 1,
            "z": 8,
            "elements": [
                "chisel:factory1@0"
            ]
        },
        {
            "x": 0,
            "y": 8,
            "z": 14,
            "elements": [
                "chisel:factory@6"
            ]
        },
        {
            "x": -9,
            "y": -1,
            "z": 4,
            "elements": [
                "chisel:technical@1"
            ]
        },
        {
            "x": -19,
            "y": -1,
            "z": 7,
            "elements": [
                "chisel:technical@1"
            ]
        },
        {
            "x": 2,
            "y": -1,
            "z": 11,
            "elements": [
                "chisel:technical@1"
            ]
        },
        {
            "x": -11,
            "y": 3,
            "z": 11,
            "elements": [
                "chisel:factory1@0"
            ]
        },
        {
            "x": -4,
            "y": 7,
            "z": 9,
            "elements": [
                "nuclearcraft:ingot_block@8"
            ]
        },
        {
            "x": -9,
            "y": 0,
            "z": 8,
            "elements": [
                "chisel:technicalnew@2"
            ]
        },
        {
            "x": -9,
            "y": -1,
            "z": 9,
            "elements": [
                "chisel:technical@1"
            ]
        },
        {
            "x": -10,
            "y": -1,
            "z": 8,
            "elements": [
                "chisel:technical@1"
            ]
        },
        {
            "x": -15,
            "y": 3,
            "z": 8,
            "elements": [
                "chisel:factory1@0"
            ]
        },
        {
            "x": -5,
            "y": 8,
            "z": 10,
            "elements": [
                "nuclearcraft:ingot_block@9"
            ]
        },
        {
            "x": -10,
            "y": 3,
            "z": 9,
            "elements": [
                "chisel:concrete_black@7"
            ]
        },
        {
            "x": -3,
            "y": 9,
            "z": 8,
            "elements": [
                "chisel:technical@10"
            ]
        },
        {
            "x": 3,
            "y": -1,
            "z": 11,
            "elements": [
                "chisel:technical@1"
            ]
        },
        {
            "x": -14,
            "y": 3,
            "z": 11,
            "elements": [
                "chisel:factory@10"
            ]
        },
        {
            "x": 0,
            "y": -1,
            "z": 4,
            "elements": [
                "chisel:technical@1"
            ]
        },
        {
            "x": 0,
            "y": 4,
            "z": 14,
            "elements": [
                "chisel:concrete_black@7"
            ]
        },
        {
            "x": -17,
            "y": -1,
            "z": 7,
            "elements": [
                "chisel:technical@1"
            ]
        },
        {
            "x": -13,
            "y": 0,
            "z": 0,

            "elements": [
                "modularmachinery:blockfluidinputhatch",
                "modularmachinery:blockmefluidinputbus"
            ]
        },
        {
            "x": -11,
            "y": 2,
            "z": 10,
            "elements": [
                "chisel:concrete_black@7"
            ]
        },
        {
            "x": 2,
            "y": -1,
            "z": 14,
            "elements": [
                "chisel:technical@1"
            ]
        },
        {
            "x": -10,
            "y": -1,
            "z": 2,
            "elements": [
                "chisel:technical@1"
            ]
        },
        {
            "x": 1,
            "y": 3,
            "z": 11,
            "elements": [
                "chisel:concrete_black@7"
            ]
        },
        {
            "x": -7,
            "y": 3,
            "z": 9,
            "elements": [
                "chisel:concrete_black@7"
            ]
        },
        {
            "x": -2,
            "y": -1,
            "z": 9,
            "elements": [
                "chisel:technical@1"
            ]
        },
        {
            "x": -17,
            "y": -1,
            "z": 0,
            "elements": [
                "chisel:technical@1"
            ]
        },
        {
            "x": -17,
            "y": -1,
            "z": 14,
            "elements": [
                "chisel:technical@1"
            ]
        },
        {
            "x": 0,
            "y": 5,
            "z": 14,
            "elements": [
                "chisel:concrete_black@7"
            ]
        },
        {
            "x": 1,
            "y": -1,
            "z": 4,
            "elements": [
                "chisel:technical@1"
            ]
        },
        {
            "x": -3,
            "y": 9,
            "z": 11,
            "elements": [
                "chisel:technicalnew@2"
            ]
        },
        {
            "x": -12,
            "y": -1,
            "z": 11,
            "elements": [
                "chisel:technical@1"
            ]
        },
        {
            "x": -11,
            "y": 0,
            "z": 10,
            "elements": [
                "chisel:technicalnew@2"
            ]
        },
        {
            "x": -14,
            "y": 1,
            "z": 11,
            "elements": [
                "chisel:technical@5"
            ]
        },
        {
            "x": 0,
            "y": 8,
            "z": 8,
            "elements": [
                "chisel:concrete_black@7"
            ]
        },
        {
            "x": -6,
            "y": -1,
            "z": 4,
            "elements": [
                "chisel:technical@1"
            ]
        },
        {
            "x": -7,
            "y": -1,
            "z": 2,
            "elements": [
                "chisel:technical@1"
            ]
        },
        {
            "x": -19,
            "y": -1,
            "z": 6,
            "elements": [
                "chisel:technical@1"
            ]
        },
        {
            "x": 0,
            "y": 6,
            "z": 14,
            "elements": [
                "chisel:concrete_black@7"
            ]
        },
        {
            "x": 1,
            "y": -1,
            "z": 9,
            "elements": [
                "chisel:technical@1"
            ]
        },
        {
            "x": 1,
            "y": 1,
            "z": 11,
            "elements": [
                "chisel:concrete_black@7"
            ]
        },
        {
            "x": -7,
            "y": 1,
            "z": 9,
            "elements": [
                "chisel:concrete_black@7"
            ]
        },
        {
            "x": -4,
            "y": 7,
            "z": 14,
            "elements": [
                "chisel:concrete_black@7"
            ]
        },
        {
            "x": 2,
            "y": 2,
            "z": 6,
            "elements": [
                "chisel:blockiron@6"
            ]
        },
        {
            "x": 1,
            "y": 6,
            "z": 11,
            "elements": [
                "chisel:concrete_black@7"
            ]
        },
        {
            "x": 1,
            "y": -1,
            "z": 7,
            "elements": [
                "chisel:technical@1"
            ]
        },
        {
            "x": -15,
            "y": 0,
            "z": 11,
            "elements": [
                "chisel:technicalnew@2"
            ]
        },
        {
            "x": -16,
            "y": -1,
            "z": 14,
            "elements": [
                "chisel:technical@1"
            ]
        },
        {
            "x": -18,
            "y": -1,
            "z": 5,
            "elements": [
                "chisel:technical@1"
            ]
        },
        {
            "x": -1,
            "y": 5,
            "z": 14,
            "elements": [
                "chisel:concrete_black@7"
            ]
        },
        {
            "x": 0,
            "y": 8,
            "z": 9,
            "elements": [
                "chisel:technical@3"
            ]
        },
        {
            "x": -11,
            "y": 2,
            "z": 8,
            "elements": [
                "chisel:concrete_black@7"
            ]
        },
        {
            "x": -1,
            "y": 8,
            "z": 8,
            "elements": [
                "nuclearcraft:ingot_block@9"
            ]
        },
        {
            "x": 1,
            "y": 7,
            "z": 11,
            "elements": [
                "chisel:concrete_black@7"
            ]
        },
        {
            "x": -15,
            "y": 1,
            "z": 11,
            "elements": [
                "chisel:technical@5"
            ]
        },
        {
            "x": -7,
            "y": 1,
            "z": 7,
            "elements": [
                "chisel:concrete_black@7"
            ]
        },
        {
            "x": 2,
            "y": 8,
            "z": 6,
            "elements": [
                "chisel:blockiron@6"
            ]
        },
        {
            "x": -4,
            "y": -1,
            "z": 2,
            "elements": [
                "chisel:technical@1"
            ]
        },
        {
            "x": -3,
            "y": 9,
            "z": 9,
            "elements": [
                "chisel:technicalnew@2"
            ]
        },
        {
            "x": -1,
            "y": 6,
            "z": 6,
            "elements": [
                "chisel:concrete_black@7"
            ]
        },
        {
            "x": -9,
            "y": 2,
            "z": 13,
            "elements": [
                "chisel:factory1@0"
            ]
        },
        {
            "x": -1,
            "y": 3,
            "z": 14,
            "elements": [
                "chisel:concrete_black@7"
            ]
        },
        {
            "x": -15,
            "y": -1,
            "z": 0,
            "elements": [
                "chisel:technical@1"
            ]
        },
        {
            "x": -1,
            "y": -1,
            "z": 12,
            "elements": [
                "chisel:technical@1"
            ]
        },
        {
            "x": -19,
            "y": -1,
            "z": 5,
            "elements": [
                "chisel:technical@1"
            ]
        },
        {
            "x": 1,
            "y": 4,
            "z": 11,
            "elements": [
                "chisel:concrete_black@7"
            ]
        },
        {
            "x": -8,
            "y": -1,
            "z": 7,
            "elements": [
                "chisel:technical@1"
            ]
        },
        {
            "x": -15,
            "y": 3,
            "z": 11,
            "elements": [
                "chisel:factory1@0"
            ]
        },
        {
            "x": 3,
            "y": -1,
            "z": 4,
            "elements": [
                "chisel:technical@1"
            ]
        },
        {
            "x": -5,
            "y": 0,
            "z": 8,
            "elements": [
                "chisel:concrete_black@7"
            ]
        },
        {
            "x": 1,
            "y": 5,
            "z": 11,
            "elements": [
                "chisel:concrete_black@7"
            ]
        },
        {
            "x": -14,
            "y": 0,
            "z": 0,

            "elements": [
                "modularmachinery:blockfluidinputhatch",
                "modularmachinery:blockmefluidinputbus"
            ]
        },
        {
            "x": -2,
            "y": 0,
            "z": 8,
            "elements": [
                "chisel:concrete_black@7"
            ]
        },
        {
            "x": -1,
            "y": 8,
            "z": 6,
            "elements": [
                "chisel:factory@6"
            ]
        },
        {
            "x": -9,
            "y": 0,
            "z": 13,
            "elements": [
                "chisel:technicalnew@2"
            ]
        },
        {
            "x": -5,
            "y": -1,
            "z": 2,
            "elements": [
                "chisel:technical@1"
            ]
        },
        {
            "x": 1,
            "y": -1,
            "z": 14,
            "elements": [
                "chisel:technical@1"
            ]
        },
        {
            "x": -15,
            "y": 2,
            "z": 11,

            "elements": [
                "mekanism:basicblock@10"
            ]
        },
        {
            "x": -17,
            "y": 0,
            "z": 5,
            "elements": [
                "chisel:technical@3"
            ]
        },
        {
            "x": 2,
            "y": 6,
            "z": 6,
            "elements": [
                "chisel:blockiron@6"
            ]
        },
        {
            "x": -18,
            "y": -1,
            "z": 0,
            "elements": [
                "chisel:technical@1"
            ]
        },
        {
            "x": -10,
            "y": 3,
            "z": 7,
            "elements": [
                "chisel:factory@6"
            ]
        },
        {
            "x": -1,
            "y": 4,
            "z": 6,

            "elements": [
                "mekanismgenerators:reactorglass@0"
            ]
        },
        {
            "x": 3,
            "y": 0,
            "z": 9,
            "elements": [
                "chisel:technical@3"
            ]
        },
        {
            "x": -5,
            "y": -1,
            "z": 7,
            "elements": [
                "chisel:technical@1"
            ]
        },
        {
            "x": 2,
            "y": -1,
            "z": 2,
            "elements": [
                "chisel:technical@1"
            ]
        },
        {
            "x": -17,
            "y": 0,
            "z": 0,

            "elements": [
                "modularmachinery:blockfluidoutputhatch",
                "modularmachinery:blockmefluidoutputbus",
                "modularmachinery:blockoutputbus",
                "modularmachinery:blockmeitemoutputbus"
            ]
        },
        {
            "x": -3,
            "y": 7,
            "z": 12,
            "elements": [
                "nuclearcraft:ingot_block@9"
            ]
        },
        {
            "x": -2,
            "y": -1,
            "z": 14,
            "elements": [
                "chisel:technical@1"
            ]
        },
        {
            "x": 1,
            "y": 0,
            "z": 8,
            "elements": [
                "chisel:factory@6"
            ]
        },
        {
            "x": 2,
            "y": -1,
            "z": 9,
            "elements": [
                "chisel:technical@1"
            ]
        },
        {
            "x": -4,
            "y": 8,
            "z": 6,
            "elements": [
                "chisel:factory@6"
            ]
        },
        {
            "x": -4,
            "y": 5,
            "z": 14,
            "elements": [
                "chisel:concrete_black@7"
            ]
        },
        {
            "x": -4,
            "y": 8,
            "z": 8,
            "elements": [
                "chisel:concrete_black@7"
            ]
        },
        {
            "x": -7,
            "y": 3,
            "z": 7,
            "elements": [
                "chisel:concrete_black@7"
            ]
        },
        {
            "x": -13,
            "y": -1,
            "z": 14,
            "elements": [
                "chisel:technical@1"
            ]
        },
        {
            "x": -3,
            "y": 8,
            "z": 9,
            "elements": [
                "chisel:concrete_black@7"
            ]
        },
        {
            "x": 2,
            "y": 0,
            "z": 6,
            "elements": [
                "chisel:blockiron@6"
            ]
        },
        {
            "x": -1,
            "y": 2,
            "z": 6,
            "elements": [
                "chisel:concrete_black@7"
            ]
        },
        {
            "x": -2,
            "y": -1,
            "z": 7,
            "elements": [
                "chisel:technical@1"
            ]
        },
        {
            "x": -16,
            "y": -1,
            "z": 11,
            "elements": [
                "chisel:technical@1"
            ]
        },
        {
            "x": 1,
            "y": 8,
            "z": 11,
            "elements": [
                "chisel:factory@6"
            ]
        },
        {
            "x": -1,
            "y": 1,
            "z": 14,
            "elements": [
                "chisel:concrete_black@7"
            ]
        },
        {
            "x": -3,
            "y": 0,
            "z": 13,
            "elements": [
                "chisel:concrete_black@7"
            ]
        },
        {
            "x": -4,
            "y": 6,
            "z": 6,
            "elements": [
                "chisel:concrete_black@7"
            ]
        },
        {
            "x": -7,
            "y": 5,
            "z": 7,
            "elements": [
                "chisel:concrete_black@7"
            ]
        },
        {
            "x": -5,
            "y": 8,
            "z": 8,
            "elements": [
                "nuclearcraft:ingot_block@9"
            ]
        },
        {
            "x": -15,
            "y": 3,
            "z": 12,
            "elements": [
                "chisel:factory1@0"
            ]
        },
        {
            "x": 2,
            "y": -1,
            "z": 12,
            "elements": [
                "chisel:technical@1"
            ]
        },
        {
            "x": 1,
            "y": 7,
            "z": 7,
            "elements": [
                "chisel:factory1@0"
            ]
        },
        {
            "x": -1,
            "y": 8,
            "z": 13,
            "elements": [
                "chisel:concrete_black@7"
            ]
        },
        {
            "x": 0,
            "y": -1,
            "z": 2,
            "elements": [
                "chisel:technical@1"
            ]
        },
        {
            "x": -1,
            "y": 0,
            "z": 8,
            "elements": [
                "chisel:concrete_black@7"
            ]
        },
        {
            "x": -19,
            "y": -1,
            "z": 11,
            "elements": [
                "chisel:technical@1"
            ]
        },
        {
            "x": -13,
            "y": -1,
            "z": 12,
            "elements": [
                "chisel:technical@1"
            ]
        },
        {
            "x": -11,
            "y": -1,
            "z": 7,
            "elements": [
                "chisel:technical@1"
            ]
        },
        {
            "x": -9,
            "y": 3,
            "z": 9,
            "elements": [
                "chisel:factory1@0"
            ]
        },
        {
            "x": 0,
            "y": 0,
            "z": 13,
            "elements": [
                "chisel:concrete_black@7"
            ]
        },
        {
            "x": -12,
            "y": -1,
            "z": 0,
            "elements": [
                "chisel:technical@1"
            ]
        },
        {
            "x": -7,
            "y": 4,
            "z": 8,
            "elements": [
                "chisel:concrete_black@7"
            ]
        },
        {
            "x": -14,
            "y": 3,
            "z": 12,
            "elements": [
                "chisel:factory1@2"
            ]
        },
        {
            "x": -19,
            "y": -1,
            "z": 14,
            "elements": [
                "chisel:technical@1"
            ]
        },
        {
            "x": -7,
            "y": 7,
            "z": 14,
            "elements": [
                "chisel:factory1@0"
            ]
        },
        {
            "x": -15,
            "y": -1,
            "z": 5,
            "elements": [
                "chisel:technical@1"
            ]
        },
        {
            "x": 1,
            "y": 9,
            "z": 7,
            "elements": [
                "chisel:technical@11"
            ]
        },
        {
            "x": 0,
            "y": 0,
            "z": 9,
            "elements": [
                "chisel:concrete_black@7"
            ]
        },
        {
            "x": -10,
            "y": 1,
            "z": 7,

            "elements": [
                "mekanismgenerators:reactorglass@0"
            ]
        },
        {
            "x": -9,
            "y": 2,
            "z": 9,
            "elements": [
                "chisel:concrete_black@7"
            ]
        },
        {
            "x": -16,
            "y": -1,
            "z": 9,
            "elements": [
                "chisel:technical@1"
            ]
        },
        {
            "x": -9,
            "y": 1,
            "z": 9,
            "elements": [
                "chisel:concrete_black@7"
            ]
        },
        {
            "x": -1,
            "y": -1,
            "z": 2,
            "elements": [
                "chisel:technical@1"
            ]
        },
        {
            "x": -7,
            "y": 2,
            "z": 8,
            "elements": [
                "chisel:concrete_black@7"
            ]
        },
        {
            "x": -15,
            "y": 0,
            "z": 9,
            "elements": [
                "chisel:technicalnew@2"
            ]
        },
        {
            "x": -14,
            "y": 1,
            "z": 12,
            "elements": [
                "chisel:factory@10"
            ]
        },
        {
            "x": -12,
            "y": -1,
            "z": 12,
            "elements": [
                "chisel:technical@1"
            ]
        },
        {
            "x": -3,
            "y": 9,
            "z": 12,
            "elements": [
                "chisel:technical@10"
            ]
        },
        {
            "x": -4,
            "y": 3,
            "z": 14,
            "elements": [
                "chisel:concrete_black@7"
            ]
        },
        {
            "x": -1,
            "y": -1,
            "z": 9,
            "elements": [
                "chisel:technical@1"
            ]
        },
        {
            "x": -7,
            "y": 8,
            "z": 8,
            "elements": [
                "chisel:factory@6"
            ]
        },
        {
            "x": -12,
            "y": 2,
            "z": 9,
            "elements": [
                "chisel:technical@3"
            ]
        },
        {
            "x": -9,
            "y": 0,
            "z": 9,
            "elements": [
                "chisel:technicalnew@2"
            ]
        },
        {
            "x": 2,
            "y": 9,
            "z": 7,
            "elements": [
                "chisel:technical@11"
            ]
        },
        {
            "x": -13,
            "y": -1,
            "z": 9,
            "elements": [
                "chisel:technical@1"
            ]
        },
        {
            "x": -2,
            "y": -1,
            "z": 2,
            "elements": [
                "chisel:technical@1"
            ]
        },
        {
            "x": -3,
            "y": 0,
            "z": 8,
            "elements": [
                "chisel:concrete_black@7"
            ]
        },
        {
            "x": -15,
            "y": 3,
            "z": 9,
            "elements": [
                "chisel:factory1@0"
            ]
        },
        {
            "x": -3,
            "y": 8,
            "z": 13,
            "elements": [
                "nuclearcraft:ingot_block@8"
            ]
        },
        {
            "x": -15,
            "y": -1,
            "z": 12,
            "elements": [
                "chisel:technical@1"
            ]
        },
        {
            "x": -10,
            "y": -1,
            "z": 9,
            "elements": [
                "chisel:technical@1"
            ]
        },
        {
            "x": -15,
            "y": 1,
            "z": 12,
            "elements": [
                "chisel:factory1@0"
            ]
        },
        {
            "x": 2,
            "y": 4,
            "z": 6,
            "elements": [
                "chisel:blockiron@6"
            ]
        },
        {
            "x": -6,
            "y": 0,
            "z": 9,
            "elements": [
                "chisel:concrete_black@7"
            ]
        },
        {
            "x": -19,
            "y": -1,
            "z": 15,
            "elements": [
                "chisel:technical@1"
            ]
        },
        {
            "x": -15,
            "y": 2,
            "z": 9,

            "elements": [
                "mekanism:basicblock@10"
            ]
        },
        {
            "x": -1,
            "y": 7,
            "z": 14,
            "elements": [
                "chisel:concrete_black@7"
            ]
        },
        {
            "x": -1,
            "y": 9,
            "z": 7,
            "elements": [
                "chisel:technical@11"
            ]
        },
        {
            "x": 1,
            "y": -1,
            "z": 2,
            "elements": [
                "chisel:technical@1"
            ]
        },
        {
            "x": -4,
            "y": 0,
            "z": 8,
            "elements": [
                "chisel:concrete_black@7"
            ]
        },
        {
            "x": -7,
            "y": -1,
            "z": 9,
            "elements": [
                "chisel:technical@1"
            ]
        },
        {
            "x": -14,
            "y": -1,
            "z": 7,
            "elements": [
                "chisel:technical@1"
            ]
        },
        {
            "x": -15,
            "y": 1,
            "z": 9,

            "elements": [
                "mekanism:basicblock@10"
            ]
        },
        {
            "x": -4,
            "y": 8,
            "z": 13,
            "elements": [
                "chisel:concrete_black@7"
            ]
        },
        {
            "x": -7,
            "y": 6,
            "z": 8,
            "elements": [
                "chisel:concrete_black@7"
            ]
        },
        {
            "x": -10,
            "y": -1,
            "z": 12,
            "elements": [
                "chisel:technical@1"
            ]
        },
        {
            "x": -9,
            "y": -1,
            "z": 0,
            "elements": [
                "chisel:technical@1"
            ]
        },
        {
            "x": -3,
            "y": 4,
            "z": 6,

            "elements": [
                "mekanismgenerators:reactorglass@0"
            ]
        },
        {
            "x": 1,
            "y": 1,
            "z": 7,
            "elements": [
                "chisel:concrete_black@7"
            ]
        },
        {
            "x": -11,
            "y": 3,
            "z": 12,
            "elements": [
                "chisel:factory1@0"
            ]
        },
        {
            "x": -7,
            "y": -1,
            "z": 7,
            "elements": [
                "chisel:technical@1"
            ]
        },
        {
            "x": -6,
            "y": 2,
            "z": 6,
            "elements": [
                "chisel:concrete_black@7"
            ]
        },
        {
            "x": -7,
            "y": 6,
            "z": 13,
            "elements": [
                "chisel:concrete_black@7"
            ]
        },
        {
            "x": -8,
            "y": -1,
            "z": 14,
            "elements": [
                "chisel:technical@1"
            ]
        },
        {
            "x": -19,
            "y": -1,
            "z": 9,
            "elements": [
                "chisel:technical@1"
            ]
        },
        {
            "x": -5,
            "y": 7,
            "z": 12,
            "elements": [
                "nuclearcraft:ingot_block@9"
            ]
        },
        {
            "x": -6,
            "y": 8,
            "z": 6,
            "elements": [
                "chisel:factory@6"
            ]
        },
        {
            "x": -6,
            "y": 1,
            "z": 14,
            "elements": [
                "chisel:concrete_black@7"
            ]
        },
        {
            "x": -13,
            "y": -1,
            "z": 3,
            "elements": [
                "chisel:technical@1"
            ]
        },
        {
            "x": 2,
            "y": -1,
            "z": 15,
            "elements": [
                "chisel:technical@1"
            ]
        },
        {
            "x": -4,
            "y": 0,
            "z": 13,
            "elements": [
                "chisel:concrete_black@7"
            ]
        },
        {
            "x": -9,
            "y": -1,
            "z": 12,
            "elements": [
                "chisel:technical@1"
            ]
        },
        {
            "x": -12,
            "y": -1,
            "z": 2,
            "elements": [
                "chisel:technical@1"
            ]
        },
        {
            "x": 0,
            "y": -1,
            "z": 7,
            "elements": [
                "chisel:technical@1"
            ]
        },
        {
            "x": -6,
            "y": 4,
            "z": 6,
            "elements": [
                "chisel:concrete_black@7"
            ]
        },
        {
            "x": -9,
            "y": 3,
            "z": 7,
            "elements": [
                "chisel:factory1@0"
            ]
        },
        {
            "x": -7,
            "y": 4,
            "z": 13,
            "elements": [
                "chisel:concrete_black@7"
            ]
        },
        {
            "x": -13,
            "y": 0,
            "z": 8,
            "elements": [
                "chisel:technicalnew@2"
            ]
        },
        {
            "x": 0,
            "y": 0,
            "z": 6,
            "elements": [
                "chisel:factory@6"
            ]
        },
        {
            "x": 0,
            "y": 0,
            "z": 1,
            "elements": [
                "chisel:technical@11"
            ]
        },
        {
            "x": -3,
            "y": 2,
            "z": 6,
            "elements": [
                "chisel:concrete_black@7"
            ]
        },
        {
            "x": -7,
            "y": -1,
            "z": 14,
            "elements": [
                "chisel:technical@1"
            ]
        },
        {
            "x": 3,
            "y": -1,
            "z": 2,
            "elements": [
                "chisel:technical@1"
            ]
        },
        {
            "x": -13,
            "y": -1,
            "z": 10,
            "elements": [
                "chisel:technical@1"
            ]
        },
        {
            "x": -7,
            "y": 1,
            "z": 14,
            "elements": [
                "chisel:factory1@0"
            ]
        },
        {
            "x": -16,
            "y": -1,
            "z": 3,
            "elements": [
                "chisel:technical@1"
            ]
        },
        {
            "x": -1,
            "y": -1,
            "z": 15,
            "elements": [
                "chisel:technical@1"
            ]
        },
        {
            "x": -16,
            "y": -1,
            "z": 4,
            "elements": [
                "chisel:technical@1"
            ]
        },
        {
            "x": -1,
            "y": 0,
            "z": 13,
            "elements": [
                "chisel:concrete_black@7"
            ]
        },
        {
            "x": 0,
            "y": 2,
            "z": 6,
            "elements": [
                "chisel:concrete_black@7"
            ]
        },
        {
            "x": -8,
            "y": 1,
            "z": 12,
            "elements": [
                "chisel:technical@3"
            ]
        },
        {
            "x": 0,
            "y": -1,
            "z": 12,
            "elements": [
                "chisel:technical@1"
            ]
        },
        {
            "x": 3,
            "y": -1,
            "z": 7,
            "elements": [
                "chisel:technical@1"
            ]
        },
        {
            "x": -19,
            "y": -1,
            "z": 4,
            "elements": [
                "chisel:technical@1"
            ]
        },
        {
            "x": -6,
            "y": 8,
            "z": 13,
            "elements": [
                "chisel:concrete_black@7"
            ]
        },
        {
            "x": -15,
            "y": 2,
            "z": 10,

            "elements": [
                "mekanism:basicblock@10"
            ]
        },
        {
            "x": -10,
            "y": -1,
            "z": 14,
            "elements": [
                "chisel:technical@1"
            ]
        },
        {
            "x": -9,
            "y": 1,
            "z": 7,
            "elements": [
                "chisel:factory1@0"
            ]
        },
        {
            "x": -12,
            "y": -1,
            "z": 5,
            "elements": [
                "chisel:technical@1"
            ]
        },
        {
            "x": 1,
            "y": 3,
            "z": 7,
            "elements": [
                "chisel:concrete_black@7"
            ]
        },
        {
            "x": -7,
            "y": 0,
            "z": 6,
            "elements": [
                "chisel:factory@6"
            ]
        },
        {
            "x": -6,
            "y": -1,
            "z": 2,
            "elements": [
                "chisel:technical@1"
            ]
        },
        {
            "x": -4,
            "y": 1,
            "z": 14,
            "elements": [
                "chisel:concrete_black@7"
            ]
        },
        {
            "x": -10,
            "y": 0,
            "z": 13,
            "elements": [
                "chisel:technicalnew@2"
            ]
        },
        {
            "x": -15,
            "y": 3,
            "z": 10,
            "elements": [
                "chisel:factory1@0"
            ]
        },
        {
            "x": -7,
            "y": 3,
            "z": 14,
            "elements": [
                "chisel:factory1@0"
            ]
        },
        {
            "x": -10,
            "y": -1,
            "z": 10,
            "elements": [
                "chisel:technical@1"
            ]
        },
        {
            "x": -3,
            "y": 6,
            "z": 6,
            "elements": [
                "chisel:concrete_black@7"
            ]
        },
        {
            "x": -11,
            "y": 2,
            "z": 13,
            "elements": [
                "chisel:factory1@0"
            ]
        },
        {
            "x": -11,
            "y": 1,
            "z": 12,
            "elements": [
                "chisel:concrete_black@7"
            ]
        },
        {
            "x": -4,
            "y": 9,
            "z": 12,
            "elements": [
                "chisel:technicalnew@2"
            ]
        },
        {
            "x": -3,
            "y": -1,
            "z": 12,
            "elements": [
                "chisel:technical@1"
            ]
        },
        {
            "x": -15,
            "y": 0,
            "z": 10,
            "elements": [
                "chisel:technicalnew@2"
            ]
        },
        {
            "x": 0,
            "y": 4,
            "z": 6,
            "elements": [
                "chisel:concrete_black@7"
            ]
        },
        {
            "x": -18,
            "y": -1,
            "z": 4,
            "elements": [
                "chisel:technical@1"
            ]
        },
        {
            "x": -17,
            "y": 0,
            "z": 4,
            "elements": [
                "chisel:technical@3"
            ]
        },
        {
            "x": -10,
            "y": -1,
            "z": 7,
            "elements": [
                "chisel:technical@1"
            ]
        },
        {
            "x": -7,
            "y": 8,
            "z": 13,
            "elements": [
                "chisel:factory@6"
            ]
        },
        {
            "x": -7,
            "y": 0,
            "z": 8,
            "elements": [
                "chisel:factory@6"
            ]
        },
        {
            "x": -9,
            "y": -1,
            "z": 5,
            "elements": [
                "chisel:technical@1"
            ]
        },
        {
            "x": -5,
            "y": -1,
            "z": 14,
            "elements": [
                "chisel:technical@1"
            ]
        },
        {
            "x": -3,
            "y": -1,
            "z": 2,
            "elements": [
                "chisel:technical@1"
            ]
        },
        {
            "x": 1,
            "y": 5,
            "z": 7,
            "elements": [
                "chisel:concrete_black@7"
            ]
        },
        {
            "x": -6,
            "y": 0,
            "z": 6,
            "elements": [
                "chisel:factory@6"
            ]
        },
        {
            "x": -11,
            "y": 0,
            "z": 13,
            "elements": [
                "chisel:technicalnew@2"
            ]
        },
        {
            "x": -15,
            "y": 1,
            "z": 10,

            "elements": [
                "mekanism:basicblock@10"
            ]
        },
        {
            "x": -7,
            "y": 5,
            "z": 14,
            "elements": [
                "chisel:factory1@0"
            ]
        },
        {
            "x": -3,
            "y": 8,
            "z": 6,
            "elements": [
                "chisel:factory@6"
            ]
        },
        {
            "x": -6,
            "y": -1,
            "z": 12,
            "elements": [
                "chisel:technical@1"
            ]
        },
        {
            "x": -10,
            "y": 2,
            "z": 13,

            "elements": [
                "mekanismgenerators:reactorglass@0"
            ]
        },
        {
            "x": -7,
            "y": 3,
            "z": 12,
            "elements": [
                "chisel:concrete_black@7"
            ]
        },
        {
            "x": 1,
            "y": 4,
            "z": 8,
            "elements": [
                "chisel:concrete_black@7"
            ]
        },
        {
            "x": -1,
            "y": 0,
            "z": 6,
            "elements": [
                "chisel:factory@6"
            ]
        },
        {
            "x": -7,
            "y": 4,
            "z": 6,
            "elements": [
                "chisel:factory1@0"
            ]
        },
        {
            "x": -3,
            "y": -1,
            "z": 7,
            "elements": [
                "chisel:technical@1"
            ]
        },
        {
            "x": -2,
            "y": 2,
            "z": 6,
            "elements": [
                "chisel:concrete_black@7"
            ]
        },
        {
            "x": -4,
            "y": -1,
            "z": 14,
            "elements": [
                "chisel:technical@1"
            ]
        },
        {
            "x": -7,
            "y": 7,
            "z": 7,
            "elements": [
                "chisel:factory1@0"
            ]
        },
        {
            "x": -16,
            "y": -1,
            "z": 10,
            "elements": [
                "chisel:technical@1"
            ]
        },
        {
            "x": -5,
            "y": -1,
            "z": 12,
            "elements": [
                "chisel:technical@1"
            ]
        },
        {
            "x": -7,
            "y": 1,
            "z": 12,
            "elements": [
                "chisel:technical@3"
            ]
        },
        {
            "x": -5,
            "y": 6,
            "z": 6,
            "elements": [
                "chisel:concrete_black@7"
            ]
        },
        {
            "x": -2,
            "y": 4,
            "z": 6,

            "elements": [
                "mekanismgenerators:reactorglass@0"
            ]
        },
        {
            "x": -7,
            "y": 2,
            "z": 6,
            "elements": [
                "chisel:factory1@0"
            ]
        },
        {
            "x": -11,
            "y": -1,
            "z": 14,
            "elements": [
                "chisel:technical@1"
            ]
        },
        {
            "x": -2,
            "y": 8,
            "z": 8,
            "elements": [
                "chisel:concrete_black@7"
            ]
        },
        {
            "x": -4,
            "y": -1,
            "z": 7,
            "elements": [
                "chisel:technical@1"
            ]
        },
        {
            "x": -3,
            "y": 1,
            "z": 14,
            "elements": [
                "chisel:technical@3"
            ]
        },
        {
            "x": 2,
            "y": 0,
            "z": 8,
            "elements": [
                "chisel:blockiron@6"
            ]
        },
        {
            "x": -4,
            "y": 0,
            "z": 6,
            "elements": [
                "chisel:factory@6"
            ]
        },
        {
            "x": -4,
            "y": -1,
            "z": 12,
            "elements": [
                "chisel:technical@1"
            ]
        },
        {
            "x": -9,
            "y": -1,
            "z": 2,
            "elements": [
                "chisel:technical@1"
            ]
        },
        {
            "x": 0,
            "y": -1,
            "z": 5,
            "elements": [
                "chisel:technical@1"
            ]
        },
        {
            "x": -5,
            "y": 0,
            "z": 13,
            "elements": [
                "chisel:concrete_black@7"
            ]
        },
        {
            "x": -12,
            "y": -1,
            "z": 4,
            "elements": [
                "chisel:technical@1"
            ]
        },
        {
            "x": 1,
            "y": 2,
            "z": 8,
            "elements": [
                "chisel:concrete_black@7"
            ]
        },
        {
            "x": -3,
            "y": 5,
            "z": 14,
            "elements": [
                "chisel:concrete_black@7"
            ]
        },
        {
            "x": -5,
            "y": 8,
            "z": 6,
            "elements": [
                "chisel:factory@6"
            ]
        },
        {
            "x": -1,
            "y": -1,
            "z": 7,
            "elements": [
                "chisel:technical@1"
            ]
        },
        {
            "x": -10,
            "y": 0,
            "z": 8,
            "elements": [
                "chisel:technicalnew@2"
            ]
        },
        {
            "x": -5,
            "y": 4,
            "z": 6,

            "elements": [
                "mekanismgenerators:reactorglass@0"
            ]
        },
        {
            "x": -6,
            "y": 6,
            "z": 6,
            "elements": [
                "chisel:concrete_black@7"
            ]
        },
        {
            "x": -6,
            "y": 7,
            "z": 14,
            "elements": [
                "chisel:factory1@0"
            ]
        },
        {
            "x": -9,
            "y": 3,
            "z": 12,
            "elements": [
                "chisel:factory1@0"
            ]
        },
        {
            "x": -14,
            "y": -1,
            "z": 14,
            "elements": [
                "chisel:technical@1"
            ]
        },
        {
            "x": -3,
            "y": 0,
            "z": 6,
            "elements": [
                "chisel:factory@6"
            ]
        },
        {
            "x": -13,
            "y": 2,
            "z": 8,
            "elements": [
                "chisel:factory1@0"
            ]
        },
        {
            "x": -2,
            "y": 9,
            "z": 11,
            "elements": [
                "chisel:technical@10"
            ]
        },
        {
            "x": -4,
            "y": 2,
            "z": 6,
            "elements": [
                "chisel:concrete_black@7"
            ]
        },
        {
            "x": 1,
            "y": 8,
            "z": 8,
            "elements": [
                "chisel:factory@6"
            ]
        },
        {
            "x": -3,
            "y": 3,
            "z": 14,
            "elements": [
                "chisel:concrete_black@7"
            ]
        },
        {
            "x": 2,
            "y": 2,
            "z": 8,
            "elements": [
                "chisel:blockiron@6"
            ]
        },
        {
            "x": -13,
            "y": -1,
            "z": 11,
            "elements": [
                "chisel:technical@1"
            ]
        },
        {
            "x": -6,
            "y": 5,
            "z": 14,
            "elements": [
                "chisel:concrete_black@7"
            ]
        },
        {
            "x": -19,
            "y": -1,
            "z": 3,
            "elements": [
                "chisel:technical@1"
            ]
        },
        {
            "x": -7,
            "y": 7,
            "z": 12,
            "elements": [
                "chisel:concrete_black@7"
            ]
        },
        {
            "x": -15,
            "y": -1,
            "z": 4,
            "elements": [
                "chisel:technical@1"
            ]
        },
        {
            "x": -7,
            "y": 2,
            "z": 13,
            "elements": [
                "chisel:concrete_black@7"
            ]
        },
        {
            "x": 3,
            "y": -1,
            "z": 5,
            "elements": [
                "chisel:technical@1"
            ]
        },
        {
            "x": -6,
            "y": 0,
            "z": 13,
            "elements": [
                "chisel:concrete_black@7"
            ]
        },
        {
            "x": 0,
            "y": 1,
            "z": 14,
            "elements": [
                "chisel:concrete_black@7"
            ]
        },
        {
            "x": -2,
            "y": 8,
            "z": 11,
            "elements": [
                "nuclearcraft:ingot_block@8"
            ]
        },
        {
            "x": -7,
            "y": -1,
            "z": 12,
            "elements": [
                "chisel:technical@1"
            ]
        },
        {
            "x": 1,
            "y": 6,
            "z": 8,
            "elements": [
                "chisel:concrete_black@7"
            ]
        },
        {
            "x": -4,
            "y": 4,
            "z": 6,

            "elements": [
                "mekanismgenerators:reactorglass@0"
            ]
        },
        {
            "x": -9,
            "y": 1,
            "z": 12,
            "elements": [
                "chisel:technical@3"
            ]
        },
        {
            "x": -17,
            "y": 0,
            "z": 3,
            "elements": [
                "chisel:technical@3"
            ]
        },
        {
            "x": 2,
            "y": 4,
            "z": 8,
            "elements": [
                "chisel:blockiron@6"
            ]
        },
        {
            "x": -7,
            "y": 6,
            "z": 6,
            "elements": [
                "chisel:factory1@0"
            ]
        },
        {
            "x": -2,
            "y": 0,
            "z": 6,
            "elements": [
                "chisel:factory@6"
            ]
        },
        {
            "x": -5,
            "y": 2,
            "z": 6,
            "elements": [
                "chisel:concrete_black@7"
            ]
        },
        {
            "x": -6,
            "y": -1,
            "z": 7,
            "elements": [
                "chisel:technical@1"
            ]
        },
        {
            "x": -7,
            "y": 5,
            "z": 12,
            "elements": [
                "chisel:concrete_black@7"
            ]
        },
        {
            "x": -1,
            "y": -1,
            "z": 14,
            "elements": [
                "chisel:technical@1"
            ]
        },
        {
            "x": -19,
            "y": -1,
            "z": 10,
            "elements": [
                "chisel:technical@1"
            ]
        },
        {
            "x": -7,
            "y": 0,
            "z": 13,
            "elements": [
                "chisel:factory@6"
            ]
        },
        {
            "x": -6,
            "y": 7,
            "z": 7,
            "elements": [
                "chisel:concrete_black@7"
            ]
        },
        {
            "x": -6,
            "y": 3,
            "z": 14,
            "elements": [
                "chisel:concrete_black@7"
            ]
        },
        {
            "x": -7,
            "y": 8,
            "z": 6,
            "elements": [
                "chisel:factory1@0"
            ]
        },
        {
            "x": -18,
            "y": -1,
            "z": 3,
            "elements": [
                "chisel:technical@1"
            ]
        },
        {
            "x": 0,
            "y": 9,
            "z": 9,
            "elements": [
                "chisel:technical@3"
            ]
        },
        {
            "x": 2,
            "y": 6,
            "z": 8,
            "elements": [
                "chisel:blockiron@6"
            ]
        },
        {
            "x": -9,
            "y": -1,
            "z": 6,
            "elements": [
                "chisel:technical@1"
            ]
        },
        {
            "x": -14,
            "y": 2,
            "z": 9,
            "elements": [
                "chisel:technical@3"
            ]
        },
        {
            "x": -11,
            "y": 0,
            "z": 9,
            "elements": [
                "chisel:technicalnew@2"
            ]
        },
        {
            "x": 1,
            "y": 0,
            "z": 14,
            "elements": [
                "chisel:factory@6"
            ]
        },
        {
            "x": -14,
            "y": 3,
            "z": 8,
            "elements": [
                "chisel:factory1@2"
            ]
        },
        {
            "x": -6,
            "y": -1,
            "z": 15,
            "elements": [
                "chisel:technical@1"
            ]
        },
        {
            "x": 3,
            "y": -1,
            "z": 13,
            "elements": [
                "chisel:technical@1"
            ]
        },
        {
            "x": 1,
            "y": 0,
            "z": 11,
            "elements": [
                "chisel:factory@6"
            ]
        },
        {
            "x": 2,
            "y": 5,
            "z": 8,
            "elements": [
                "chisel:blockiron@6"
            ]
        },
        {
            "x": -1,
            "y": 1,
            "z": 0,

            "elements": [
                "modularmachinery:blockcasing@0"
            ]
        },
        {
            "x": 0,
            "y": -1,
            "z": 0,
            "elements": [
                "chisel:technical@1"
            ]
        },
        {
            "x": -2,
            "y": 4,
            "z": 14,
            "elements": [
                "chisel:concrete_black@7"
            ]
        },
        {
            "x": -15,
            "y": -1,
            "z": 7,
            "elements": [
                "chisel:technical@1"
            ]
        },
        {
            "x": -3,
            "y": -1,
            "z": 5,
            "elements": [
                "chisel:technical@1"
            ]
        },
        {
            "x": 0,
            "y": -1,
            "z": 14,
            "elements": [
                "chisel:technical@1"
            ]
        },
        {
            "x": -5,
            "y": 0,
            "z": 6,
            "elements": [
                "chisel:factory@6"
            ]
        },
        {
            "x": -5,
            "y": 8,
            "z": 13,
            "elements": [
                "chisel:concrete_black@7"
            ]
        },
        {
            "x": -5,
            "y": 1,
            "z": 6,
            "elements": [
                "chisel:concrete_black@7"
            ]
        },
        {
            "x": 1,
            "y": 5,
            "z": 13,
            "elements": [
                "chisel:concrete_black@7"
            ]
        },
        {
            "x": -12,
            "y": 2,
            "z": 11,
            "elements": [
                "chisel:technical@3"
            ]
        },
        {
            "x": -4,
            "y": -1,
            "z": 10,
            "elements": [
                "chisel:technical@1"
            ]
        },
        {
            "x": -13,
            "y": 2,
            "z": 9,
            "elements": [
                "chisel:technical@3"
            ]
        },
        {
            "x": -5,
            "y": 8,
            "z": 11,
            "elements": [
                "chisel:concrete_black@7"
            ]
        },
        {
            "x": -2,
            "y": 5,
            "z": 14,
            "elements": [
                "chisel:concrete_black@7"
            ]
        },
        {
            "x": -2,
            "y": 6,
            "z": 11,
            "elements": [
                "nuclearcraft:ingot_block@8"
            ]
        },
        {
            "x": -6,
            "y": -1,
            "z": 6,
            "elements": [
                "chisel:technical@1"
            ]
        },
        {
            "x": -15,
            "y": -1,
            "z": 14,
            "elements": [
                "chisel:technical@1"
            ]
        },
        {
            "x": -14,
            "y": 0,
            "z": 7,
            "elements": [
                "chisel:technical@3"
            ]
        },
        {
            "x": -13,
            "y": 0,
            "z": 2,
            "elements": [
                "chisel:technical@3"
            ]
        },
        {
            "x": 1,
            "y": 8,
            "z": 12,
            "elements": [
                "chisel:factory@6"
            ]
        },
        {
            "x": -14,
            "y": 1,
            "z": 7,
            "elements": [
                "chisel:technical@3"
            ]
        },
        {
            "x": 2,
            "y": 8,
            "z": 8,
            "elements": [
                "chisel:blockiron@6"
            ]
        },
        {
            "x": -14,
            "y": 2,
            "z": 8,
            "elements": [
                "chisel:factory@10"
            ]
        },
        {
            "x": 1,
            "y": 2,
            "z": 14,
            "elements": [
                "chisel:factory1@0"
            ]
        },
        {
            "x": 1,
            "y": 4,
            "z": 13,
            "elements": [
                "chisel:concrete_black@7"
            ]
        },
        {
            "x": 1,
            "y": -1,
            "z": 0,
            "elements": [
                "chisel:technical@1"
            ]
        },
        {
            "x": -2,
            "y": 8,
            "z": 13,
            "elements": [
                "chisel:concrete_black@7"
            ]
        },
        {
            "x": -2,
            "y": 6,
            "z": 14,
            "elements": [
                "chisel:concrete_black@7"
            ]
        },
        {
            "x": 1,
            "y": 6,
            "z": 13,
            "elements": [
                "chisel:concrete_black@7"
            ]
        },
        {
            "x": -4,
            "y": -1,
            "z": 5,
            "elements": [
                "chisel:technical@1"
            ]
        },
        {
            "x": -7,
            "y": 5,
            "z": 10,
            "elements": [
                "chisel:concrete_black@7"
            ]
        },
        {
            "x": -5,
            "y": -1,
            "z": 10,
            "elements": [
                "chisel:technical@1"
            ]
        },
        {
            "x": 1,
            "y": 6,
            "z": 9,
            "elements": [
                "chisel:concrete_black@7"
            ]
        },
        {
            "x": 1,
            "y": 1,
            "z": 14,
            "elements": [
                "chisel:factory1@0"
            ]
        },
        {
            "x": -9,
            "y": -1,
            "z": 15,
            "elements": [
                "chisel:technical@1"
            ]
        },
        {
            "x": 1,
            "y": 3,
            "z": 13,
            "elements": [
                "chisel:concrete_black@7"
            ]
        },
        {
            "x": -14,
            "y": 1,
            "z": 8,
            "elements": [
                "chisel:technical@5"
            ]
        },
        {
            "x": 2,
            "y": 7,
            "z": 8,
            "elements": [
                "chisel:blockiron@6"
            ]
        },
        {
            "x": -17,
            "y": -1,
            "z": 2,
            "elements": [
                "chisel:technical@1"
            ]
        },
        {
            "x": -18,
            "y": -1,
            "z": 14,
            "elements": [
                "chisel:technical@1"
            ]
        },
        {
            "x": -7,
            "y": 3,
            "z": 10,
            "elements": [
                "chisel:concrete_black@7"
            ]
        },
        {
            "x": 1,
            "y": 5,
            "z": 14,
            "elements": [
                "chisel:factory1@0"
            ]
        },
        {
            "x": -2,
            "y": -1,
            "z": 10,
            "elements": [
                "chisel:technical@1"
            ]
        },
        {
            "x": -14,
            "y": 0,
            "z": 8,
            "elements": [
                "chisel:technicalnew@2"
            ]
        },
        {
            "x": 1,
            "y": 7,
            "z": 13,
            "elements": [
                "chisel:factory1@0"
            ]
        },
        {
            "x": -3,
            "y": -1,
            "z": 13,
            "elements": [
                "chisel:technical@1"
            ]
        },
        {
            "x": -15,
            "y": -1,
            "z": 6,
            "elements": [
                "chisel:technical@1"
            ]
        },
        {
            "x": -2,
            "y": 7,
            "z": 14,
            "elements": [
                "chisel:concrete_black@7"
            ]
        },
        {
            "x": 1,
            "y": 0,
            "z": 6,
            "elements": [
                "chisel:factory@6"
            ]
        },
        {
            "x": -17,
            "y": 1,
            "z": 7,
            "elements": [
                "chisel:technical@3"
            ]
        },
        {
            "x": 1,
            "y": 1,
            "z": 0,

            "elements": [
                "modularmachinery:blockcasing@0"
            ]
        },
        {
            "x": -17,
            "y": 1,
            "z": 8,
            "elements": [
                "chisel:technical@3"
            ]
        },
        {
            "x": 1,
            "y": 8,
            "z": 13,
            "elements": [
                "chisel:factory@6"
            ]
        },
        {
            "x": -2,
            "y": -1,
            "z": 0,
            "elements": [
                "chisel:technical@1"
            ]
        },
        {
            "x": -15,
            "y": -1,
            "z": 8,
            "elements": [
                "chisel:technical@1"
            ]
        },
        {
            "x": -1,
            "y": -1,
            "z": 5,
            "elements": [
                "chisel:technical@1"
            ]
        },
        {
            "x": -15,
            "y": -1,
            "z": 3,
            "elements": [
                "chisel:technical@1"
            ]
        },
        {
            "x": -9,
            "y": 0,
            "z": 11,
            "elements": [
                "chisel:technicalnew@2"
            ]
        },
        {
            "x": 1,
            "y": 1,
            "z": 6,
            "elements": [
                "chisel:factory1@0"
            ]
        },
        {
            "x": 1,
            "y": 6,
            "z": 14,
            "elements": [
                "chisel:factory1@0"
            ]
        },
        {
            "x": -2,
            "y": 0,
            "z": 13,
            "elements": [
                "chisel:concrete_black@7"
            ]
        },
        {
            "x": -14,
            "y": -1,
            "z": 2,
            "elements": [
                "chisel:technical@1"
            ]
        },
        {
            "x": -8,
            "y": -1,
            "z": 15,
            "elements": [
                "chisel:technical@1"
            ]
        },
        {
            "x": -2,
            "y": 8,
            "z": 14,
            "elements": [
                "chisel:factory@6"
            ]
        },
        {
            "x": -5,
            "y": 7,
            "z": 14,
            "elements": [
                "chisel:concrete_black@7"
            ]
        },
        {
            "x": 1,
            "y": 3,
            "z": 14,
            "elements": [
                "chisel:factory1@0"
            ]
        },
        {
            "x": -11,
            "y": 2,
            "z": 9,
            "elements": [
                "chisel:technical@5"
            ]
        },
        {
            "x": -10,
            "y": 0,
            "z": 9,
            "elements": [
                "chisel:technicalnew@2"
            ]
        },
        {
            "x": -7,
            "y": 1,
            "z": 10,
            "elements": [
                "chisel:concrete_black@7"
            ]
        },
        {
            "x": 2,
            "y": -1,
            "z": 3,
            "elements": [
                "chisel:technical@1"
            ]
        },
        {
            "x": -7,
            "y": 7,
            "z": 10,
            "elements": [
                "chisel:concrete_black@7"
            ]
        },
        {
            "x": -18,
            "y": -1,
            "z": 7,
            "elements": [
                "chisel:technical@1"
            ]
        },
        {
            "x": -6,
            "y": -1,
            "z": 5,
            "elements": [
                "chisel:technical@1"
            ]
        },
        {
            "x": 1,
            "y": 4,
            "z": 14,
            "elements": [
                "chisel:factory1@0"
            ]
        },
        {
            "x": -9,
            "y": 2,
            "z": 11,
            "elements": [
                "chisel:concrete_black@7"
            ]
        },
        {
            "x": 3,
            "y": -1,
            "z": 14,
            "elements": [
                "chisel:technical@1"
            ]
        },
        {
            "x": -13,
            "y": 0,
            "z": 9,
            "elements": [
                "chisel:technicalnew@2"
            ]
        },
        {
            "x": -7,
            "y": -1,
            "z": 10,
            "elements": [
                "chisel:technical@1"
            ]
        },
        {
            "x": -2,
            "y": 0,
            "z": 11,
            "elements": [
                "chisel:concrete_black@7"
            ]
        },
        {
            "x": -11,
            "y": -1,
            "z": 2,
            "elements": [
                "chisel:technical@1"
            ]
        },
        {
            "x": 0,
            "y": -1,
            "z": 6,
            "elements": [
                "chisel:technical@1"
            ]
        },
        {
            "x": -5,
            "y": 8,
            "z": 14,
            "elements": [
                "chisel:factory@6"
            ]
        },
        {
            "x": -2,
            "y": 3,
            "z": 14,
            "elements": [
                "chisel:concrete_black@7"
            ]
        },
        {
            "x": -7,
            "y": -1,
            "z": 15,
            "elements": [
                "chisel:technical@1"
            ]
        },
        {
            "x": -9,
            "y": 3,
            "z": 10,
            "elements": [
                "chisel:factory1@0"
            ]
        },
        {
            "x": -5,
            "y": 5,
            "z": 14,
            "elements": [
                "chisel:concrete_black@7"
            ]
        },
        {
            "x": 1,
            "y": 4,
            "z": 6,
            "elements": [
                "chisel:factory1@0"
            ]
        },
        {
            "x": -11,
            "y": 1,
            "z": 7,
            "elements": [
                "chisel:factory1@0"
            ]
        },
        {
            "x": -12,
            "y": -1,
            "z": 14,
            "elements": [
                "chisel:technical@1"
            ]
        },
        {
            "x": -2,
            "y": 2,
            "z": 14,
            "elements": [
                "chisel:concrete_black@7"
            ]
        },
        {
            "x": 1,
            "y": 0,
            "z": 9,
            "elements": [
                "chisel:factory@6"
            ]
        },
        {
            "x": 1,
            "y": 3,
            "z": 12,
            "elements": [
                "chisel:concrete_black@7"
            ]
        },
        {
            "x": -2,
            "y": 8,
            "z": 12,
            "elements": [
                "chisel:concrete_black@7"
            ]
        },
        {
            "x": 3,
            "y": -1,
            "z": 0,
            "elements": [
                "chisel:technical@1"
            ]
        },
        {
            "x": -5,
            "y": 4,
            "z": 14,
            "elements": [
                "chisel:concrete_black@7"
            ]
        },
        {
            "x": -5,
            "y": 6,
            "z": 14,
            "elements": [
                "chisel:concrete_black@7"
            ]
        },
        {
            "x": -9,
            "y": -1,
            "z": 3,
            "elements": [
                "chisel:technical@1"
            ]
        },
        {
            "x": 1,
            "y": -1,
            "z": 5,
            "elements": [
                "chisel:technical@1"
            ]
        },
        {
            "x": -10,
            "y": -1,
            "z": 15,
            "elements": [
                "chisel:technical@1"
            ]
        },
        {
            "x": -3,
            "y": 0,
            "z": 11,
            "elements": [
                "chisel:concrete_black@7"
            ]
        },
        {
            "x": -5,
            "y": 3,
            "z": 14,
            "elements": [
                "chisel:concrete_black@7"
            ]
        },
        {
            "x": -11,
            "y": 0,
            "z": 7,
            "elements": [
                "chisel:technicalnew@2"
            ]
        },
        {
            "x": -2,
            "y": 9,
            "z": 12,
            "elements": [
                "chisel:technicalnew@2"
            ]
        },
        {
            "x": -2,
            "y": 1,
            "z": 14,
            "elements": [
                "chisel:concrete_black@7"
            ]
        },
        {
            "x": -2,
            "y": 8,
            "z": 6,
            "elements": [
                "chisel:factory@6"
            ]
        },
        {
            "x": -10,
            "y": 1,
            "z": 10,
            "elements": [
                "chisel:technical@3"
            ]
        },
        {
            "x": 3,
            "y": -1,
            "z": 6,
